Workbook

Sheet INSTRUCCIONES
A1: DASHBOARD FINANCIERO — EMPRESA PESQUERA
A2: Guía de uso y estructura del archivo
A6: 📋 ESTRUCTURA DEL ARCHIVO
A7: Hoja | B7: Descripción
A8: INSTRUCCIONES | B8: Esta hoja — guía de uso
A9: CARGA_DIARIA | B9: Acá cargás los datos todos los días (una fila por día)
A10: ACTIVO_CORRIENTE | B10: Desglose diario de activos: bancos, cheques, divisas, créditos, FCI
A11: GASTOS_DIARIOS | B11: Detalle de egresos por sector (13 categorías)
A12: PASIVO_CORRIENTE | B12: Compromisos y deudas a corto plazo
A13: VENCIMIENTOS | B13: Cheques a cobrar y pagar en los próximos 30 días
A14: AJUSTES | B14: Stock a precio de venta, posición fiscal, otras deudas
A15: POSICION_NETA | B15: Hoja de cálculo automática — no modificar
A17: 🎨 CONVENCIÓN DE COLORES
A18: Color | B18: Significado
A19: Texto AZUL | B19: Dato a ingresar manualmente (input)
A20: Texto NEGRO | B20: Fórmula calculada automáticamente — no modificar
A21: Texto VERDE | B21: Vínculo a otra hoja del mismo archivo
A22: Fondo AMARILLO | B22: Celda importante que requiere atención o actualización
A24: 📌 INSTRUCCIONES DE CARGA DIARIA
A25: 1. | B25: Abrir la hoja CARGA_DIARIA
A26: 2. | B26: Ir a la última fila con datos e insertar una nueva fila debajo
A27: 3. | B27: Ingresar la fecha del día en la columna A (formato DD/MM/AAAA)
A28: 4. | B28: Ingresar el tipo de cambio BNA del día en la columna B
A29: 5. | B29: Completar el resto de columnas con los valores en PESOS del día
A30: 6. | B30: Los valores en USD se calculan automáticamente dividiendo por el TC
A31: 7. | B31: La hoja POSICION_NETA se actualiza automáticamente
A33: ⚠️ IMPORTANTE
A34: • | B34: No eliminar ni mover filas de encabezado
A35: • | B35: No modificar las hojas de fórmulas (POSICION_NETA)
A36: • | B36: Siempre cargar valores en PESOS — el dashboard convierte a USD
A37: • | B37: Los cheques en cartera cargar en hoja VENCIMIENTOS con fecha de acreditación
A38: • | B38: Guardar el archivo con Ctrl+S después de cada carga

Sheet CARGA_DIARIA
A1: CARGA DIARIA — POSICIÓN FINANCIERA | Valores en PESOS argentinos (ARS)
A2: FECHA | B2: TIPO DE CAMBIO BNA (ARS/USD) | C2: ACTIVO CORRIENTE (ARS) | J2: GASTOS DEL DÍA POR SECTOR (ARS) | W2: PASIVO CORRIENTE (ARS)
A3: Fecha | B3: TC BNA (ARS/USD) | C3: Efectivo (MI) | D3: Cheques en cartera | E3: Banco Patagonia | F3: Banco Galicia | G3: Banco Francés | H3: Banco Santander | I3: Créditos MI | J3: Proveedores | K3: Aranceles y Cánones | L3: Comercio Exterior | M3: Directores / Accionistas | N3: Empresas del Grupo | O3: Gastos de Buques | P3: Impuestos y Tasas | Q3: RRHH | R3: Servicios Varios | S3: Retiros Particulares | T3: Pago Importaciones | U3: Compra Dólares (CCL) | V3: Pago Préstamos | W3: Otros Gastos | X3: Cheques Emitidos | Y3: Gs. Presup. Próximos | Z3: Préstamos ML (ARS) | AA3: Deuda Proveed. MI | AB3: Deuda Proveed. Ext. (USD) | AC3: Préstamos ME (USD) | AD3: Intereses Proy. (USD) | AE3: Otras Deudas (USD) | AF3: Stock a Precio Venta (USD) | AG3: Posición Fiscal | AH3: Divisas Disp. (ARS eq.) | AI3: Créditos Exterior (ARS eq.) | AJ3: Inversiones FCI
A4: 46029 | B4: 1463 | C4: 0 | D4: 147143953 | E4: -17312000 | F4: 0 | G4: 5368000 | H4: 6913000 | I4: 984848664 | J4: 93118000 | K4: 0 | L4: 0 | M4: 0 | N4: 0 | O4: 0 | P4: 0 | Q4: 331346284 | R4: 0 | S4: 0 | T4: 0 | U4: 0 | V4: 0 | W4: 0 | X4: 396177166 | Y4: 2543380519 | Z4: 220357000 | AA4: 4106866784 | AB4: 2600000 | AC4: 6975000 | AD4: 159934 | AE4: 2044803 | AF4: 6441928 | AG4: 4314967894 | AH4: 6208398504 | AI4: 4836302009 | AJ4: 1972327480
A5: 46030 | B5: 1469 | C5: 0 | D5: 1.4714395e+08 | E5: 103831332 | F5: 0 | G5: 24804818 | H5: 3794000 | I5: 1127668632 | J5: 98556000 | K5: 0 | L5: 0 | M5: 0 | N5: 0 | O5: 0 | P5: 366732120 | Q5: 3010892.1 | R5: 0 | S5: 0 | T5: 45929347 | U5: 0 | V5: 0 | W5: 0 | X5: 3.4308383e+08 | Y5: 2493689353 | Z5: 220357000 | AA5: 4094188807 | AB5: 2600000 | AC5: 6975000 | AD5: 159934 | AE5: 2044803 | AF5: 6480455 | AG5: 4314967894 | AH5: 6110180635 | AI5: 4816967051 | AJ5: 422641035
A6: 46031 | B6: 1455 | C6: 0 | D6: 102302314 | E6: 63095000 | F6: 0 | G6: 14747000 | H6: 12301000 | I6: 996009122 | J6: 2347817 | K6: 0 | L6: 0 | M6: 0 | N6: 0 | O6: 0 | P6: 126421132 | Q6: 7044405 | R6: 0 | S6: 0 | T6: 0 | U6: 0 | V6: 0 | W6: 0 | X6: 5.0635025e+08 | Y6: 1113182008 | Z6: 220357000 | AA6: 4182158189 | AB6: 2600000 | AC6: 6975000 | AD6: 159934 | AE6: 2044803 | AF6: 7740751.2 | AG6: 4314967894 | AH6: 5581783035 | AI6: 4658234880 | AJ6: 422947645
A7: 46034 | B7: 1465.5 | C7: 0 | D7: 1.9119589e+08 | E7: 19902000 | F7: 0 | G7: 1103000 | H7: 309000 | I7: 1129839976 | J7: 38460000 | K7: 0 | L7: 23625223 | M7: 0 | N7: 0 | O7: 0 | P7: 109006535 | Q7: 224149787 | R7: 0 | S7: 0 | T7: 0 | U7: 0 | V7: 0 | W7: 0 | X7: 717079149 | Y7: 944499841 | Z7: 220357000 | AA7: 4087351389 | AB7: 2600000 | AC7: 6975000 | AD7: 159934 | AE7: 2344803 | AF7: 8315409 | AG7: 4314967894 | AH7: 4.4868554e+09 | AI7: 4988005110 | AJ7: 423827578
A8: 46035 | B8: 1462 | C8: 0 | D8: 191195891 | E8: 41915000 | F8: 0 | G8: 15637889 | H8: 0 | I8: 1129839976 | J8: 167756834 | K8: 0 | L8: 39116189 | M8: 0 | N8: 0 | O8: 0 | P8: 15121860 | Q8: 180946598 | R8: 0 | S8: 0 | T8: 0 | U8: 0 | V8: 0 | W8: 0 | X8: 828454859 | Y8: 705798673 | Z8: 220357000 | AA8: 3882411723 | AB8: 2600000 | AC8: 6975000 | AD8: 159934 | AE8: 2344803 | AF8: 8965227.5 | AG8: 4314967894 | AH8: 4284443632 | AI8: 4.7138135e+09 | AJ8: 424124427
A9: 46036 | B9: 1464.5 | C9: 0 | D9: 62480863 | E9: 60536771 | F9: 0 | G9: 25159457 | H9: 0 | I9: 1143603954 | J9: 170000000 | K9: 0 | L9: 0 | M9: 0 | N9: 0 | O9: 0 | P9: 0 | Q9: 183177718 | R9: 0 | S9: 0 | T9: 0 | U9: 0 | V9: 0 | W9: 0 | X9: 938129312 | Y9: 569683193 | Z9: 220357000 | AA9: 3764632228 | AB9: 2600000 | AC9: 6975000 | AD9: 159934 | AE9: 2344803 | AF9: 8783530.6 | AG9: 4314967894 | AH9: 4.0926902e+09 | AI9: 4.672764e+09 | AJ9: 424459423
A10: 46037 | B10: 1450 | C10: 0 | D10: 62480863 | E10: 74751000 | F10: 0 | G10: 9758000 | H10: 0 | I10: 1214275683 | J10: 276864200 | K10: 0 | L10: 1009800 | M10: 0 | N10: 0 | O10: 0 | P10: 0 | Q10: 10591254 | R10: 0 | S10: 0 | T10: 0 | U10: 194000000 | V10: 0 | W10: 0 | X10: 7.6483029e+08 | Y10: 604673438 | Z10: 220357000 | AA10: 3766894667 | AB10: 2600000 | AC10: 6975000 | AD10: 159934 | AE10: 2344803 | AF10: 8886136.3 | AG10: 4314967894 | AH10: 4231934388 | AI10: 4759593100 | AJ10: 1.9461029e+08
A11: 46038 | B11: 1440 | C11: 0 | D11: 170748138 | E11: 164880000 | F11: 0 | G11: -3450000 | H11: 0 | I11: 1096607000 | J11: 1.8091383e+08 | K11: 0 | L11: 2919605 | M11: 0 | N11: 0 | O11: 0 | P11: 7054822 | Q11: 3191483 | R11: 0 | S11: 0 | T11: 0 | U11: 0 | V11: 0 | W11: 0 | X11: 995710009 | Y11: 487074663 | Z11: 220357000 | AA11: 3172758684 | AB11: 2600000 | AC11: 6975000 | AD11: 159934 | AE11: 2344803 | AF11: 9582201.9 | AG11: 4314967894 | AH11: 4.0730687e+09 | AI11: 4577526720 | AJ11: 611311.33
A12: 46041 | B12: 1428 | C12: 0 | D12: 170748138 | E12: 176500595 | F12: 0 | G12: 9812921 | H12: 0 | I12: 1098875342 | J12: 93270575 | K12: 0 | L12: 30686642 | M12: 0 | N12: 0 | O12: 0 | P12: 0 | Q12: 2786622 | R12: 106064322 | S12: 0 | T12: 0 | U12: 0 | V12: 0 | W12: 0 | X12: 727601822 | Y12: 55545741 | Z12: 220357000 | AA12: 3286079509 | AB12: 2600000 | AC12: 6975000 | AD12: 159934 | AE12: 2194803 | AF12: 10991009 | AG12: 4314967894 | AH12: 3.6198033e+09 | AI12: 4647360312 | AJ12: 612693
A13: 46042 | B13: 1428.5 | C13: 0 | D13: 1.3831084e+08 | E13: 73444051 | F13: 0 | G13: 15092051 | H13: 0 | I13: 1039256943 | J13: 173300000 | K13: 0 | L13: 0 | M13: 0 | N13: 0 | O13: 0 | P13: 0 | Q13: 157286696 | R13: 0 | S13: 0 | T13: 0 | U13: 180000000 | V13: 0 | W13: 0 | X13: 763073132 | Y13: 801275230 | Z13: 220357000 | AA13: 3.2430649e+09 | AB13: 2600000 | AC13: 6975000 | AD13: 159934 | AE13: 2194803 | AF13: 11490332 | AG13: 4314967894 | AH13: 3.5524671e+09 | AI13: 4648987539 | AJ13: 613144.98
A14: 46043 | B14: 1432 | C14: 0 | D14: 1.1489068e+08 | E14: 84544429 | F14: 0 | G14: 8979855 | H14: 0 | I14: 1039256943 | J14: 107253172 | K14: 0 | L14: 27735508 | M14: 0 | N14: 0 | O14: 43586760 | P14: 144447864 | Q14: 37176621 | R14: 0 | S14: 0 | T14: 0 | U14: 0 | V14: 0 | W14: 0 | X14: 759957476 | Y14: 624555549 | Z14: 220357000 | AA14: 3592955206 | AB14: 2600000 | AC14: 6975000 | AD14: 159934 | AE14: 2194803 | AF14: 12252881 | AG14: 4314967894 | AH14: 3.5743475e+09 | AI14: 4087129912 | AJ14: 613592.34
A15: 46044 | B15: 1427 | C15: 0 | D15: 61294019 | E15: 4.0495235e+08 | F15: 0 | G15: 8492957.3 | H15: 4032000 | I15: 1039256943 | J15: 133501600 | K15: 0 | L15: 80264892 | M15: 0 | N15: 0 | O15: 0 | P15: 19105502 | Q15: 1046236 | R15: 176000 | S15: 0 | T15: 0 | U15: 0 | V15: 0 | W15: 0 | X15: 6.8531777e+08 | Y15: 570093319 | Z15: 220357000 | AA15: 3.5088838e+09 | AB15: 2600000 | AC15: 6975000 | AD15: 159934 | AE15: 2194803 | AF15: 12482991 | AG15: 4314967894 | AH15: 3.4281362e+09 | AI15: 4072859207 | AJ15: 614057
... A82: 46149 | B82: 1383 | C82: 0 | D82: 1004100985 | E82: 56178000 | F82: 13243000 | G82: 4270000 | H82: 2000000 | I82: 1586995953 | J82: 0 | K82: 0 | L82: 0 | M82: 0 | N82: 0 | O82: 0 | P82: 0 | Q82: 0 | R82: 0 | S82: 0 | T82: 0 | U82: 0 | V82: 0 | W82: 0 | X82: 1.2373028e+09 | Y82: 2896014463 | Z82: 2.0273466e+08 | AA82: 7174765725 | AB82: 1196248.6 | AC82: 9000000 | AD82: 141199.47 | AE82: 280000 | AF82: 12657304 | AG82: 5582721359 | AH82: 2731278746 | AI82: 8858339046 | AJ82: 102471144
A83: 46150 | B83: 1388 | D83: 1026676615 | E83: 160451000 | F83: 50895000 | G83: 2169000 | H83: 1428000 | I83: 1617879590 | J83: 284346273 | L83: 204023840 | P83: 2425645 | Q83: 13418493 | X83: 1738503267 | Y83: 2698378718 | Z83: 2.0273466e+08 | AA83: 6689223249 | AB83: 1196248.6 | AC83: 9000000 | AD83: 141199.47 | AE83: 280000 | AF83: 12737370 | AG83: 5582721359 | AH83: 2088518048 | AI83: 8890364856 | AJ83: 90511582
A84: 46153 | B84: 1389 | D84: 1026676615 | E84: 177905205 | F84: 26207670 | G84: -42250000 | H84: 2000000 | I84: 1897154988 | J84: 60206933 | K84: 86098436 | L84: 46609610 | P84: 49239273 | Q84: 1226584509 | R84: 4462000 | X84: 1697009243 | Y84: 1215298412 | Z84: 2.0273466e+08 | AA84: 6649944967 | AB84: 1196248.6 | AC84: 10000000 | AD84: 141199.47 | AE84: 280000 | AF84: 12946008 | AG84: 5582721359 | AH84: 2272274354 | AI84: 9463757040 | AJ84: 90663001
A85: 46154 | B85: 1391 | D85: 1026676615 | E85: -39733000 | F85: 54938000 | G85: 7516000 | H85: 2000000 | I85: 1897154988 | J85: 350881600 | O85: 4687440 | Q85: 119797908 | X85: 2193914554 | Y85: 1224485195 | Z85: 2.0273466e+08 | AA85: 5996923699 | AB85: 1100365 | AC85: 10000000 | AD85: 141199.47 | AE85: 280000 | AF85: 12953742 | AG85: 5582721359 | AH85: 2.5270541e+09 | AI85: 9477383760 | AJ85: 90673439
A86: 46155 | B86: 1382.5 | D86: 1049061340 | E86: 82398000 | F86: 238635000 | G86: 5524000 | H86: 2000000 | I86: 1871991100 | J86: 194004331 | L86: 6881904 | P86: 4499179 | Q86: 298337009 | U86: 120000000 | X86: 1951558798 | Y86: 991611113 | Z86: 2.0273466e+08 | AA86: 6063339939 | AB86: 1100365 | AC86: 10000000 | AD86: 141199.47 | AE86: 280000 | AF86: 12416677 | AG86: 5582721359 | AH86: 2.3394629e+09 | AI86: 9419470200 | AJ86: 140735000
A87: 46156 | B87: 1386 | D87: =+'[1]CF Dia V1'!$CJ$10 -> 837432835 | E87: =+'[1]CF Dia V1'!$CJ$13 -> 78949000 | F87: =+'[1]CF Dia V1'!$CJ$16 -> 45656000 | G87: =+'[1]CF Dia V1'!$CJ$14 -> 5783000 | H87: =+'[1]CF Dia V1'!$CJ$15 -> 2000000 | I87: =+'[1]CF Dia V1'!$CJ$22 -> 1740123570 | J87: =+'[1]CF Dia V1'!$CJ$43 -> 458483114 | K87: =+'[1]CF Dia V1'!$CJ$45 -> 0 | L87: =+'[1]CF Dia V1'!$CJ$46 -> 14376000 | M87: =+'[1]CF Dia V1'!$CJ$47 -> 0 | N87: =+'[1]CF Dia V1'!$CJ$48 -> 0 | O87: =+'[1]CF Dia V1'!$CJ$49 -> 0 | P87: =+'[1]CF Dia V1'!$CJ$50 -> 0 | Q87: =+'[1]CF Dia V1'!$CJ$51 -> 6873443 | R87: =+'[1]CF Dia V1'!$CJ$53 -> 0 | S87: =+'[1]CF Dia V1'!$CJ$56 -> 0 | T87: =+'[1]CF Dia V1'!$CJ$59 -> 0 | U87: =+'[1]CF Dia V1'!$CJ$60 -> 30000000 | V87: =+'[1]CF Dia V1'!$CJ$68 -> 0 | W87: =+'[1]CF Dia V1'!$CJ$61 -> 0 | X87: =+'[1]CF Dia V1'!$CJ$100 -> 1689393489 | Y87: =+'[1]CF Dia V1'!$CJ$101 -> 990744710 | Z87: =+'[1]CF Dia V1'!$CJ$104 -> 2.0273466e+08 | AA87: =+'[1]CF Dia V1'!$CJ$102 -> 6063777655 | AB87: =+'[1]CF Dia V1'!$CJ$103 -> 1100365 | AC87: =+'[1]CF Dia V1'!$CJ$105 -> 10000000 | AD87: =+'[1]CF Dia V1'!$CJ$106 -> 141199.47 | AE87: =+'[1]CF Dia V1'!$CJ$107 -> 280000 | AF87: =+'[1]CF Dia V1'!$CJ$97 -> 7845303 | AG87: =+'[1]CF Dia V1'!$CJ$98 -> 5582721359 | AH87: =+'[1]CF Dia V1'!$CJ$24+'[1]CF Dia V1'!$CJ$25 -> 3.5648957e+09 | AI87: =+'[1]CF Dia V1'!$CJ$29 -> 8574762042 | AJ87: =+'[1]CF Dia V1'!$CJ$31 -> 1.4029793e+08
A88: 46157 | B88: 1392 | D88: =+'[1]CF Dia V1'!$CK$10 -> 850726335 | E88: =+'[1]CF Dia V1'!$CK$13 -> 55135000 | F88: =+'[1]CF Dia V1'!$CK$16 -> 35083000 | G88: =+'[1]CF Dia V1'!$CK$14 -> 6687413 | H88: =+'[1]CF Dia V1'!$CK$15 -> 2000000 | I88: =+'[1]CF Dia V1'!$CK$22 -> 1726830070 | J88: =+'[1]CF Dia V1'!$CK$43 -> 661233493 | L88: =+'[1]CF Dia V1'!$CK$46 -> 9499387 | P88: =+'[1]CF Dia V1'!$CK$50 -> 9401592 | Q88: =+'[1]CF Dia V1'!$CK$51 -> 10840885 | X88: =+'[1]CF Dia V1'!$CK$100 -> 1583396236 | Y88: =+'[1]CF Dia V1'!$CK$101 -> 771360669 | Z88: =+'[1]CF Dia V1'!$CK$104 -> 2.0273466e+08 | AA88: =+'[1]CF Dia V1'!$CK$102 -> 5851473775 | AB88: =+'[1]CF Dia V1'!$CK$103 -> 1100365 | AC88: =+'[1]CF Dia V1'!$CK$105 -> 10000000 | AD88: 220000 | AE88: =+'[1]CF Dia V1'!$CK$107 -> 280000 | AF88: =+'[1]CF Dia V1'!$CK$97 -> 6352071 | AG88: =+'[1]CF Dia V1'!$CK$98 -> 5582721359 | AH88: =+'[1]CF Dia V1'!$CK$24+'[1]CF Dia V1'!$CK$25 -> 3.3216693e+09 | AI88: =+'[1]CF Dia V1'!$CK$29 -> 8569053168 | AJ88: =+'[1]CF Dia V1'!$CK$31 -> 170372226
A89: 46160 | B89: 1392.5 | D89: 958457035 | E89: 52780000 | F89: 11055319 | G89: 6146000 | H89: =+'[1]CF Dia V1'!$CK$15 -> 2000000 | I89: 1635289293 | J89: 267891646 | P89: 45594750 | Q89: 76176394 | U89: 100000000 | X89: 1537867977 | Y89: 695105278 | Z89: =+'[1]CF Dia V1'!$CK$104 -> 2.0273466e+08 | AA89: 5792810924 | AB89: 1048306.4 | AC89: 10000000 | AD89: 220000 | AE89: 280000 | AF89: 11256611 | AG89: =+'[1]CF Dia V1'!$CK$98 -> 5582721359 | AH89: =+'[1]CF Dia V1'!$CL$24+'[1]CF Dia V1'!$CL$25 -> 2.8193139e+09 | AI89: =+'[1]CF Dia V1'!$CL$29 -> 9272841310 | AJ89: =+'[1]CF Dia V1'!$CL$31 -> 1.8661942e+08
A90: 46161 | B90: 1390 | D90: 1007436112 | E90: 57028000 | F90: 256616000 | G90: 25612301 | H90: 2000000 | I90: 1583330883 | J90: =+'[1]CF Dia V1'!$CM$43 -> 345281349 | L90: =+'[1]CF Dia V1'!$CM$46 -> 8048613 | Q90: =+'[1]CF Dia V1'!$CM$51 -> 77515155 | U90: 30000000 | X90: 2531313482 | Y90: 824238787 | Z90: =+Z89 -> 2.0273466e+08 | AA90: 6003601474 | AB90: =+AB89 -> 1048306.4 | AC90: 10000000 | AD90: 220000 | AE90: 280000 | AF90: 9237646.3 | AG90: =+AG89 -> 5582721359 | AH90: =+'[1]CF Dia V1'!$CM$24+'[1]CF Dia V1'!$CM$25 -> 2.7330969e+09 | AI90: =+'[1]CF Dia V1'!$CM$29 -> 9256193480 | AJ90: =+'[1]CF Dia V1'!$CM$31 -> 186701425
A91: =+'[1]CF Dia V1'!$CN$1 -> 46162 | B91: =+'[1]CF Dia V1'!$CN$2 -> 1395.5 | D91: =+'[1]CF Dia V1'!$CN$10 -> 747534542 | E91: =+'[1]CF Dia V1'!$CN$13 -> 209536000 | F91: =+'[1]CF Dia V1'!$CN$16 -> 1.5237856e+08 | G91: =+'[1]CF Dia V1'!$CN$14 -> 60202000 | H91: =+'[1]CF Dia V1'!$CN$15 -> 2000000 | I91: =+'[1]CF Dia V1'!$CN$22 -> 1628502061 | J91: =+'[1]CF Dia V1'!$CN$43 -> 434891710 | L91: =+'[1]CF Dia V1'!$CN$46 -> 0 | O91: =+'[1]CF Dia V1'!$CN$50 -> 8039538 | U91: =+'[1]CF Dia V1'!$CN$60 -> 110000000 | X91: =+'[1]CF Dia V1'!$CN$100 -> 2211799335 | Y91: =+'[1]CF Dia V1'!$CN$101 -> 886288208 | Z91: =+Z90 -> 2.0273466e+08 | AA91: =+'[1]CF Dia V1'!$CN$102 -> 6003847969 | AB91: =+AB90 -> 1048306.4 | AC91: =+AC90 -> 10000000 | AD91: =+AD90 -> 220000 | AE91: =+AE90 -> 280000 | AF91: =+'[1]CF Dia V1'!$CN$97 -> 6348809 | AG91: =+AG90 -> 5582721359 | AH91: =+'[1]CF Dia V1'!$CN$24+'[1]CF Dia V1'!$CN$25 -> 2.9791712e+09 | AI91: =+'[1]CF Dia V1'!$CN$29 -> 9.0989265e+09 | AJ91: =+'[1]CF Dia V1'!$CN$31 -> 1.8678328e+08
A92: =+'[1]CF Dia V1'!$CO$1 -> 46163 | B92: =+B91 -> 1395.5 | D92: =+'[1]CF Dia V1'!$CO$10 -> 935271863 | E92: =+'[1]CF Dia V1'!$CO$13 -> 164501000 | F92: =+'[1]CF Dia V1'!$CO$16 -> 109500000 | G92: =+'[1]CF Dia V1'!$CO$14 -> 9150000 | H92: =+H91 -> 2000000 | I92: =+'[1]CF Dia V1'!$CO$22 -> 1642654898 | J92: =+'[1]CF Dia V1'!$CO$43 -> 327757232 | L92: =+'[1]CF Dia V1'!$CO$46 -> 0 | O92: =+'[1]CF Dia V1'!$CO$49 -> 85437900 | P92: =+'[1]CF Dia V1'!$CO$50 -> 59668977 | Q92: =+'[1]CF Dia V1'!$CO$51 -> 80898077 | X92: =+'[1]CF Dia V1'!$CO$100 -> 2022241225 | Y92: =+'[1]CF Dia V1'!$CO$101 -> 821747346 | Z92: =+Z91 -> 2.0273466e+08 | AA92: =+'[1]CF Dia V1'!$CO$102 -> 6263281746 | AB92: =+AB91 -> 1048306.4 | AC92: =+AC91 -> 10000000 | AD92: =+AD91 -> 220000 | AE92: =+AE91 -> 280000 | AF92: =+'[1]CF Dia V1'!$CO$97 -> 5162809 | AG92: =+AG91 -> 5582721359 | AH92: =+'[1]CF Dia V1'!$CO$24+'[1]CF Dia V1'!$CO$25 -> 2.8774722e+09 | AI92: =+'[1]CF Dia V1'!$CO$29 -> 9.0989265e+09 | AJ92: =+'[1]CF Dia V1'!$CO$31 -> 1.8687428e+08
A93: =+'[1]CF Dia V1'!$CP$1 -> 46164 | B93: =+'[1]CF Dia V1'!$CP$2 -> 1390 | D93: =+'[1]CF Dia V1'!$CP$10 -> 901607908 | E93: =+'[1]CF Dia V1'!$CP$13 -> -12018000 | F93: =+'[1]CF Dia V1'!$CP$16 -> 31400000 | G93: =+'[1]CF Dia V1'!$CP$14 -> 9062000 | H93: =+'[1]CF Dia V1'!$CP$15 -> 2876000 | I93: =+'[1]CF Dia V1'!$CP$22 -> 1143093119 | J93: =+'[1]CF Dia V1'!$CP$43 -> 350616029 | L93: =+'[1]CF Dia V1'!$CP$46 -> 0 | O93: =+'[1]CF Dia V1'!$CP$49 -> 948120 | P93: =+'[1]CF Dia V1'!$CP$50 -> 21504816 | Q93: =+'[1]CF Dia V1'!$CP$51 -> 271146305 | X93: =+'[1]CF Dia V1'!$CP$100 -> 2.2309233e+09 | Y93: =+'[1]CF Dia V1'!$CP$101 -> 970095427 | Z93: =+'[1]CF Dia V1'!$CP$104 -> 2.0273466e+08 | AA93: =+'[1]CF Dia V1'!$CP$102 -> 5815616379 | AB93: =+AB92 -> 1048306.4 | AC93: =+AC92 -> 10000000 | AD93: =+AD92 -> 220000 | AE93: =+AE92 -> 280000 | AF93: =+'[1]CF Dia V1'!$CP$97 -> 4784062 | AG93: =+AG92 -> 5582721359 | AH93: =+'[1]CF Dia V1'!$CP$24+'[1]CF Dia V1'!$CP$25 -> 3010733050 | AI93: =+'[1]CF Dia V1'!$CP$29 -> 9293453820 | AJ93: =+'[1]CF Dia V1'!$CP$31 -> 1.8696528e+08
A94: 46168 | B94: =+'[1]CF Dia V1'!$CQ$2 -> 1392 | D94: =+'[1]CF Dia V1'!$CQ$10 -> 1224537171 | E94: =+'[1]CF Dia V1'!$CQ$13 -> 149182000 | F94: =+'[1]CF Dia V1'!$CQ$16 -> 52639000 | G94: =+'[1]CF Dia V1'!$CQ$14 -> 9150000 | H94: =+'[1]CF Dia V1'!$CQ$15 -> 2000000 | I94: =+'[1]CF Dia V1'!$CQ$22 -> 1190510533 | J94: =+'[1]CF Dia V1'!$CQ$43 -> 418065530 | L94: =+'[1]CF Dia V1'!$CQ$46 -> 18256232 | O94: =+'[1]CF Dia V1'!$CQ$49 -> 4500474 | Q94: =+'[1]CF Dia V1'!$CQ$51 -> 36096372 | X94: =+'[1]CF Dia V1'!$CQ$100 -> 1816083018 | Y94: =+'[1]CF Dia V1'!$CQ$101 -> 851827495 | Z94: =+Z93 -> 2.0273466e+08 | AA94: =+'[1]CF Dia V1'!$CQ$102 -> 5807216200 | AB94: =+AB93 -> 1048306.4 | AC94: =+AC93 -> 10000000 | AD94: =+AD93 -> 220000 | AE94: =+AE93 -> 280000 | AF94: =+'[1]CF Dia V1'!$CQ$97 -> 4873216 | AG94: =+AG93 -> 5582721359 | AH94: =+'[1]CF Dia V1'!$CQ$24+'[1]CF Dia V1'!$CQ$25 -> 3.3752674e+09 | AI94: =+'[1]CF Dia V1'!$CQ$29 -> 9433283328 | AJ94: =+'[1]CF Dia V1'!$CQ$31 -> 2.3338884e+08
A95: =+'[1]CF Dia V1'!$CR$1 -> 46169 | B95: =+'[1]CF Dia V1'!$CR$2 -> 1406 | D95: =+D94 -> 1224537171 | E95: =+'[1]CF Dia V1'!$CR$13 -> 183468000 | F95: =+'[1]CF Dia V1'!$CR$16 -> 87439376 | G95: =+G94 -> 9150000 | H95: =+H94 -> 2000000 | I95: =+'[1]CF Dia V1'!$CR$22 -> 1190510533 | J95: =+'[1]CF Dia V1'!$CR$43 -> 471654657 | L95: =+'[1]CF Dia V1'!$CR$46 -> 1649700 | Q95: =+'[1]CF Dia V1'!$CR$51 -> 46281564 | U95: =+'[1]CF Dia V1'!$CR$60 -> 29000000 | X95: =+'[1]CF Dia V1'!$CR$100 -> 1437358611 | Y95: =+'[1]CF Dia V1'!$CR$101 -> 786178943 | Z95: =+Z94 -> 2.0273466e+08 | AA95: =+'[1]CF Dia V1'!$CR$102 -> 5719924121 | AB95: =+AB94 -> 1048306.4 | AC95: =+AC94 -> 10000000 | AD95: =+AD94 -> 220000 | AE95: =+AE94 -> 280000 | AF95: =+'[1]CF Dia V1'!$CR$97 -> 6457477 | AG95: =+AG94 -> 5582721359 | AH95: =+'[1]CF Dia V1'!$CR$24+'[1]CF Dia V1'!$CR$25 -> 4.7760327e+09 | AI95: =+'[1]CF Dia V1'!$CR$29 -> 7743577338 | AJ95: =+'[1]CF Dia V1'!$CR$31 -> 2.4209525e+08
A96: 46170 | B96: 1408 | D96: =+'[1]CF Dia V1'!$CS$10 -> 1224537171 | E96: =+'[1]CF Dia V1'!$CS$13 -> 139852000 | F96: =+'[1]CF Dia V1'!$CS$16 -> 165500000 | G96: =+'[1]CF Dia V1'!$CS$14 -> 13379850 | H96: 2000000 | I96: =+'[1]CF Dia V1'!$CS$22 -> 1290599938 | J96: =+'[1]CF Dia V1'!$CS$43+'[1]CF Dia V1'!$CS$44 -> 457355720 | L96: =+'[1]CF Dia V1'!$CS$46 -> 90081817 | Q96: =+'[1]CF Dia V1'!$CS$51 -> 104935725 | X96: =+'[1]CF Dia V1'!$CS$100 -> 1452001433 | Y96: =+'[1]CF Dia V1'!$CS$101 -> 809592824 | Z96: =+Z95 -> 2.0273466e+08 | AA96: =+'[1]CF Dia V1'!$CS$102 -> 4896254184 | AB96: =+AB95 -> 1048306.4 | AC96: =+AC95 -> 10000000 | AD96: =+AD95 -> 220000 | AE96: =+AE95 -> 280000 | AF96: =+'[1]CF Dia V1'!$CS$97 -> 6316844 | AG96: =+AG95 -> 5582721359 | AH96: =+'[1]CF Dia V1'!$CS$24+'[1]CF Dia V1'!$CS$25 -> 4.659497e+09 | AI96: =+'[1]CF Dia V1'!$CS$29 -> 7917403648 | AJ96: =+'[1]CF Dia V1'!$CS$31 -> 2.4220163e+08
A97: 46171 | B97: 1406.5 | D97: =+'[1]CF Dia V1'!$CT$10 -> 1340551975 | E97: =+'[1]CF Dia V1'!$CT$13 -> -33045000 | F97: =+'[1]CF Dia V1'!$CT$16 -> 35632000 | G97: =+'[1]CF Dia V1'!$CT$14 -> 13378000 | H97: 2000000 | I97: =+'[1]CF Dia V1'!$CT$22 -> 1250668537 | J97: =+'[1]CF Dia V1'!$CT$43+'[1]CF Dia V1'!$CT$44 -> 447130211 | Q97: =+'[1]CF Dia V1'!$CT$51 -> 69975466 | X97: =+'[1]CF Dia V1'!$CT$100 -> 1377152179 | Y97: =+'[1]CF Dia V1'!$CT$101 -> 898433033 | Z97: =+Z96 -> 2.0273466e+08 | AA97: =+'[1]CF Dia V1'!$CT$102 -> 4628913889 | AB97: =+AB96 -> 1048306.4 | AC97: =+AC96 -> 10000000 | AD97: =+AD96 -> 220000 | AE97: =+AE96 -> 280000 | AF97: =+'[1]CF Dia V1'!$CT$97 -> 35688 | AG97: =+AG96 -> 5582721359 | AH97: =+'[1]CF Dia V1'!$CT$24+'[1]CF Dia V1'!$CT$25 -> 4.3574672e+09 | AI97: =+'[1]CF Dia V1'!$CT$29 -> 7908968914 | AJ97: =+'[1]CF Dia V1'!$CT$31 -> 2.4230821e+08
A98: 46174 | B98: 1406 | D98: =+'[1]CF Dia V1'!$CU$10 -> 1366573012 | E98: 310683000 | F98: =+'[1]CF Dia V1'!$CU$16 -> 447324554 | G98: =+'[1]CF Dia V1'!$CU$14 -> 13146882 | H98: =+H97 -> 2000000 | I98: =+'[1]CF Dia V1'!$CU$22 -> 1213336989 | J98: =+'[1]CF Dia V1'!$CU$43 -> 325345795 | L98: =+'[1]CF Dia V1'!$CU$46 -> 116687046 | Q98: =+'[1]CF Dia V1'!$CU$51 -> 5414532 | X98: =+'[1]CF Dia V1'!$CU$100 -> 1213908811 | Y98: =+'[1]CF Dia V1'!$CU$101 -> 3753759654 | Z98: =+'[1]CF Dia V1'!$CU$104 -> 1.9101677e+08 | AA98: =+'[1]CF Dia V1'!$CU$102 -> 4562436968 | AB98: =+'[1]CF Dia V1'!$CU$103 -> 1028533.4 | AC98: =+AC97 -> 10000000 | AD98: =+AD97 -> 220000 | AE98: =+AE97 -> 280000 | AF98: =+'[1]CF Dia V1'!$CU$97 -> 7045070 | AG98: =+'[1]CF Dia V1'!$CU$98 -> 5582721359 | AH98: =+'[1]CF Dia V1'!$CU$24+'[1]CF Dia V1'!$CU$25 -> 4.4391961e+09 | AI98: =+'[1]CF Dia V1'!$CU$29 -> 8951903580 | AJ98: =+'[1]CF Dia V1'!$CU$31 -> 2.7867305e+08
A99: 46175 | B99: 1419 | D99: =+'[1]CF Dia V1'!$CV$10 -> 1366573012 | E99: =+'[1]CF Dia V1'!$CV$13 -> 62158000 | F99: =+'[1]CF Dia V1'!$CV$16 -> 90927000 | G99: =+'[1]CF Dia V1'!$CV$14 -> 9121127 | H99: =+H98 -> 2000000 | I99: =+'[1]CF Dia V1'!$CV$22 -> 1533043002 | J99: =+'[1]CF Dia V1'!$CV$43 -> 365000923 | Q99: =+'[1]CF Dia V1'!$CV$51 -> 80000000 | X99: =+'[1]CF Dia V1'!$CV$100 -> 1507567585 | Y99: =+'[1]CF Dia V1'!$CV$101 -> 4031972319 | Z99: =+'[1]CF Dia V1'!$CV$104 -> 1.9101677e+08 | AA99: =+'[1]CF Dia V1'!$CV$102 -> 4496965997 | AB99: =+AB98 -> 1028533.4 | AC99: =+AC98 -> 10000000 | AD99: =+AD98 -> 220000 | AE99: =+AE98 -> 280000 | AF99: =+'[1]CF Dia V1'!$CV$97 -> 8074763 | AG99: =+AG98 -> 5582721359 | AH99: =+'[1]CF Dia V1'!$CV$24+'[1]CF Dia V1'!$CV$25 -> 4.4802413e+09 | AI99: =+'[1]CF Dia V1'!$CV$29 -> 8676102303 | AJ99: =+'[1]CF Dia V1'!$CV$31 -> 2.8579827e+08
A100: 46176 | B100: 1424.5 | D100: =+'[1]CF Dia V1'!$CW$10 -> 1366573012 | E100: =+'[1]CF Dia V1'!$CW$13 -> 193021000 | F100: =+'[1]CF Dia V1'!$CW$16 -> 120900000 | G100: =+'[1]CF Dia V1'!$CW$14 -> 3910000 | H100: =+H99 -> 2000000 | I100: =+'[1]CF Dia V1'!$CW$22 -> 1582834654 | J100: =+'[1]CF Dia V1'!$CW$43 -> 214487540 | Q100: =+'[1]CF Dia V1'!$CW$51 -> 178059700 | T100: =+'[1]CF Dia V1'!$CW$59 -> 11508455 | U100: =+'[1]CF Dia V1'!$CW$60 -> 100000000 | X100: =+'[1]CF Dia V1'!$CW$100 -> 1512097058 | Y100: =+'[1]CF Dia V1'!$CW$101 -> 3816902319 | Z100: =+Z99 -> 1.9101677e+08 | AA100: =+'[1]CF Dia V1'!$CW$102 -> 4472804706 | AB100: =+AB99 -> 1028533.4 | AC100: =+AC99 -> 10000000 | AD100: =+AD99 -> 220000 | AE100: =+AE99 -> 280000 | AF100: =+'[1]CF Dia V1'!$CW$97 -> 8485763 | AG100: =+AG99 -> 5582721359 | AH100: =+'[1]CF Dia V1'!$CW$24+'[1]CF Dia V1'!$CW$25 -> 4.5662692e+09 | AI100: =+'[1]CF Dia V1'!$CW$29 -> 8.7097306e+09 | AJ100: =+'[1]CF Dia V1'!$CW$31 -> 2.8592274e+08
A101: 46177 | B101: 1430 | D101: =+'[1]CF Dia V1'!$CX$10 -> 1366573012 | E101: =+'[1]CF Dia V1'!$CX$13 -> 97642000 | F101: =+'[1]CF Dia V1'!$CX$16 -> 13500000 | G101: =+'[1]CF Dia V1'!$CX$14 -> 5149000 | H101: =+H100 -> 2000000 | I101: =+'[1]CF Dia V1'!$CX$22 -> 1733927373 | J101: =+'[1]CF Dia V1'!$CX$43 -> 135000000 | L101: =+'[1]CF Dia V1'!$CX$46 -> 3892372 | P101: =+'[1]CF Dia V1'!$CX$50 -> 11667763 | Q101: =+'[1]CF Dia V1'!$CX$51 -> 481974372 | X101: =+'[1]CF Dia V1'!$CX$100 -> 1485119936 | Y101: =+'[1]CF Dia V1'!$CX$101 -> 3427374844 | Z101: =+Z100 -> 1.9101677e+08 | AA101: =+'[1]CF Dia V1'!$CX$102 -> 4799416274 | AB101: =+AB100 -> 1028533.4 | AC101: =+AC100 -> 10000000 | AD101: =+AD100 -> 220000 | AE101: =+AE100 -> 280000 | AF101: =+'[1]CF Dia V1'!$CX$97 -> 8825768 | AG101: =+AG100 -> 5582721359 | AH101: =+'[1]CF Dia V1'!$CX$24+'[1]CF Dia V1'!$CX$25 -> 4.9306105e+09 | AI101: =+'[1]CF Dia V1'!$CX$29 -> 8743351760 | AJ101: =+'[1]CF Dia V1'!$CX$31 -> 2.8604565e+08
A102: 46178 | B102: 1434 | D102: =+'[1]CF Dia V1'!$CY$10 -> 1366573012 | E102: =+'[1]CF Dia V1'!$CY$13 -> 2.7264047e+08 | F102: =+'[1]CF Dia V1'!$CY$16 -> 20650975 | G102: =+'[1]CF Dia V1'!$CY$14 -> 16335000 | H102: =+H101 -> 2000000 | I102: =+'[1]CF Dia V1'!$CY$22 -> 1654368586 | J102: =+'[1]CF Dia V1'!$CY$43 -> 440719000 | Q102: =+'[1]CF Dia V1'!$CY$51 -> 83213406 | T102: =+'[1]CF Dia V1'!$CY$59 -> 10652000 | X102: =+'[1]CF Dia V1'!$CY$100 -> 1499323745 | Y102: =+'[1]CF Dia V1'!$CY$101 -> 3574582194 | Z102: =+Z101 -> 1.9101677e+08 | AA102: =+'[1]CF Dia V1'!$CY$102 -> 4744842059 | AB102: =+AB101 -> 1028533.4 | AC102: =+AC101 -> 10000000 | AD102: =+AD101 -> 220000 | AE102: =+AE101 -> 280000 | AF102: =+'[1]CF Dia V1'!$CY$97 -> 10993000 | AG102: =+AG101 -> 5582721359 | AH102: =+'[1]CF Dia V1'!$CY$24+'[1]CF Dia V1'!$CY$25 -> 4.8576236e+09 | AI102: =+'[1]CF Dia V1'!$CY$29 -> 7931454000 | AJ102: =+'[1]CF Dia V1'!$CY$31 -> 2.6415992e+08
A103: 46181 | B103: 1440 | D103: =+'[1]CF Dia V1'!$CZ$10 -> 1366573012 | E103: =+'[1]CF Dia V1'!$CZ$13 -> 82078000 | F103: =+'[1]CF Dia V1'!$CZ$16 -> 19099000 | G103: =+'[1]CF Dia V1'!$CZ$14 -> -55055000 | H103: =+H102 -> 2000000 | I103: =+'[1]CF Dia V1'!$CZ$22 -> 2504434234 | J103: =+'[1]CF Dia V1'!$CZ$43 -> 464435608 | L103: =+'[1]CF Dia V1'!$CZ$46 -> 126723515 | Q103: =+'[1]CF Dia V1'!$CZ$51 -> 8388083 | U103: =+'[1]CF Dia V1'!$CZ$60 -> 100000000 | X103: =+'[1]CF Dia V1'!$CZ$100 -> 1122265222 | Y103: =+'[1]CF Dia V1'!$CZ$101 -> 3203368814 | Z103: =+Z102 -> 1.9101677e+08 | AA103: =+'[1]CF Dia V1'!$CZ$102 -> 5023890065 | AB103: 1202456 | AC103: =+AC102 -> 10000000 | AD103: =+AD102 -> 220000 | AE103: =+AE102 -> 280000 | AF103: =+'[1]CF Dia V1'!$CZ$97 -> 10901124 | AG103: =+AG102 -> 5582721359 | AH103: =+'[1]CF Dia V1'!$CZ$24+'[1]CF Dia V1'!$CZ$25 -> 4.7756018e+09 | AI103: =+'[1]CF Dia V1'!$CZ$29 -> 8096941440 | AJ103: =+'[1]CF Dia V1'!$CZ$31 -> 278518000
A104: 46182 | B104: =+'[1]CF Dia V1'!$DA$2 -> 1442 | D104: =+D103 -> 1366573012 | E104: =+'[1]CF Dia V1'!$DA$13 -> 158003000 | F104: =+'[1]CF Dia V1'!$DA$16 -> 83500000 | G104: =+'[1]CF Dia V1'!$DA$14 -> 3455000 | H104: =+H103 -> 2000000 | I104: =+'[1]CF Dia V1'!$DA$22 -> 2504434234 | J104: =+'[1]CF Dia V1'!$DA$43 -> 26208000 | P104: =+'[1]CF Dia V1'!$DA$50 -> 230621763 | Q104: =+'[1]CF Dia V1'!$DA$51 -> 999147178 | X104: =+'[1]CF Dia V1'!$DA$100 -> 1442191789 | Y104: =+'[1]CF Dia V1'!$DA$101 -> 2351933757 | Z104: =+Z103 -> 1.9101677e+08 | AA104: =+'[1]CF Dia V1'!$DA$102 -> 5.3296562e+09 | AB104: =+AB103 -> 1202456 | AC104: =+AC103 -> 10000000 | AD104: =+AD103 -> 220000 | AE104: =+AE103 -> 280000 | AF104: =+'[1]CF Dia V1'!$DA$97 -> 10661367 | AG104: =+AG103 -> 5582721359 | AH104: =+'[1]CF Dia V1'!$DA$24+'[1]CF Dia V1'!$DA$25 -> 4.2778097e+09 | AI104: =+'[1]CF Dia V1'!$DA$29 -> 8051598786 | AJ104: =+'[1]CF Dia V1'!$DA$31 -> 278638000
A105: 46183 | B105: 1444 | D105: =+D104 -> 1366573012 | E105: =+'[1]CF Dia V1'!$DB$13 -> 2.823776e+08 | F105: =+'[1]CF Dia V1'!$DB$16 -> 404000000 | G105: =+G104 -> 3455000 | H105: =+H104 -> 2000000 | I105: =+'[1]CF Dia V1'!$DB$22 -> 2519698829 | J105: =+'[1]CF Dia V1'!$DB$43 -> 49230696 | L105: =+'[1]CF Dia V1'!$DB$46 -> 176339266 | P105: =+'[1]CF Dia V1'!$DB$50 -> 124006883 | Q105: =+'[1]CF Dia V1'!$DB$51 -> 413477248 | U105: =+'[1]CF Dia V1'!$DB$60 -> 60000000 | X105: =+'[1]CF Dia V1'!$DB$100 -> 2069933438 | Y105: =+'[1]CF Dia V1'!$DB$101 -> 2032148193 | Z105: =+Z104 -> 1.9101677e+08 | AA105: =+'[1]CF Dia V1'!$DB$102 -> 5465695997 | AB105: =+AB104 -> 1202456 | AC105: =+AC104 -> 10000000 | AD105: =+AD104 -> 220000 | AE105: =+AE104 -> 280000 | AF105: =+'[1]CF Dia V1'!$DB$97 -> 9665367 | AG105: =+AG104 -> 5582721359 | AH105: =+'[1]CF Dia V1'!$DB$24+'[1]CF Dia V1'!$DB$25 -> 3295069376 | AI105: =+'[1]CF Dia V1'!$DB$29 -> 8062766052 | AJ105: =+'[1]CF Dia V1'!$DB$31 -> 178714000
A106: 46185 | B106: 1444 | D106: =+'[1]CF Dia V1'!$DD$10 -> 1778551709 | E106: =+'[1]CF Dia V1'!$DD$13 -> 1.4093515e+08 | F106: =+'[1]CF Dia V1'!$DD$16 -> 290571568 | G106: =+'[1]CF Dia V1'!$DD$14 -> 6748560 | H106: 2000000 | I106: =+'[1]CF Dia V1'!$DD$22 -> 2018496354 | J106: =+'[1]CF Dia V1'!$DD$43 -> 422611775 | P106: =+'[1]CF Dia V1'!$DD$50 -> 285064171 | Q106: =+'[1]CF Dia V1'!$DD$51 -> 306986818 | X106: =+'[1]CF Dia V1'!$DD$100 -> 1873319205 | Y106: =+'[1]CF Dia V1'!$DD$101 -> 1563095825 | Z106: =+Z105 -> 1.9101677e+08 | AA106: =+'[1]CF Dia V1'!$DD$102 -> 5589564137 | AB106: =+AB105 -> 1202456 | AC106: =+AC105 -> 10000000 | AD106: =+AD105 -> 220000 | AE106: =+AE105 -> 280000 | AF106: =+'[1]CF Dia V1'!$DD$97 -> 11289324 | AG106: =+AG105 -> 5582721359 | AH106: =+'[1]CF Dia V1'!$DD$24+'[1]CF Dia V1'!$DD$25 -> 4.0563256e+09 | AI106: =+'[1]CF Dia V1'!$DD$29 -> 7951640144 | AJ106: =+'[1]CF Dia V1'!$DD$31 -> 1.9405327e+08
...

Sheet CREDITOS_EXTERIOR
A1: CRÉDITOS POR VENTAS AL EXTERIOR — Facturas de exportación pendientes de cobro
A2: N° Factura | B2: Cliente (País) | C2: Fecha Factura | D2: Fecha Vto. | E2: Días al vto. | F2: Monto (USD) | G2: TC estimado | H2: ARS equivalente | I2: Estado
A3: EXP-2026-041 | B3: Nordic Fish AS (Noruega) | C3: 46096 | D3: 46157 | E3: =IFERROR(D3-TODAY(),"") -> -164 | F3: 320000 | G3: 1197 | H3: =IFERROR(F3*G3,0) -> 383040000 | I3: Pendiente
A4: EXP-2026-055 | B4: Iberian Seafood SL (España) | C4: 46113 | D4: 46172 | E4: =IFERROR(D4-TODAY(),"") -> -149 | F4: 185000 | G4: 1197 | H4: =IFERROR(F4*G4,0) -> 221445000 | I4: Pendiente
A5: EXP-2026,062 | B5: Ocean Trade LLC (EEUU) | C5: 46122 | D5: 46183 | E5: =IFERROR(D5-TODAY(),"") -> -138 | F5: 240000 | G5: 1197 | H5: =IFERROR(F5*G5,0) -> 287280000 | I5: Pendiente
A6: EXP-2026-071 | B6: Maruha Nichiro (Japón) | C6: 46132 | D6: 46193 | E6: =IFERROR(D6-TODAY(),"") -> -128 | F6: 495000 | G6: 1197 | H6: =IFERROR(F6*G6,0) -> 592515000 | I6: Pendiente

Sheet DIVISAS
A1: DIVISAS DISPONIBLES — Seguimiento diario de posición en USD
A2: Fecha | B2: TC BNA | C2: Patag. (USD) | D2: Francés (USD) | E2: Total USD | F2: Liquidado hoy (USD)
A3: 46140 | B3: 1194 | C3: 285000 | D3: 140000 | E3: =C3+D3 -> 425000 | F3: 87000
A4: 46141 | B4: 1196 | C4: 268000 | D4: 135000 | E4: =C4+D4 -> 403000 | F4: 72000
A5: 46142 | B5: 1197 | C5: 301000 | D5: 148000 | E5: =C5+D5 -> 449000 | F5: 95000
A6: 46144 | B6: 1198.5 | C6: 275000 | D6: 128000 | E6: =C6+D6 -> 403000 | F6: 68000
A7: 46147 | B7: 1197 | C7: 285000 | D7: 140000 | E7: =C7+D7 -> 425000 | F7: 87000

Sheet VENCIMIENTOS
A1: VENCIMIENTOS — Cheques a cobrar y compromisos de pago próximos
A2: Ingresá cada cheque o compromiso con su fecha exacta. El dashboard lo muestra en el calendario de vencimientos.
A3: Fecha | B3: Tipo | C3: Descripción / Contraparte | D3: Monto (ARS) | E3: TC del día | F3: Monto (USD) | G3: Estado
A4: 46148 | B4: COBRO | C4: Cheque acreditación — Cliente Norte | D4: 42000000 | E4: 1197 | F4: =IFERROR(D4/E4,0) -> 35087.719 | G4: Pendiente
A5: 46149 | B5: PAGO | C5: Proveedor Pescadores del Sur | D5: 87000000 | E5: 1197 | F5: =IFERROR(D5/E5,0) -> 72681.704 | G5: Pendiente
A6: 46150 | B6: COBRO | C6: Cheque — Distribuidora Atlántica | D6: 65000000 | E6: 1197 | F6: =IFERROR(D6/E6,0) -> 54302.423 | G6: Pendiente
A7: 46151 | B7: PAGO | C7: Cuota préstamo Banco Galicia | D7: 48500000 | E7: 1197 | F7: =IFERROR(D7/E7,0) -> 40517.962 | G7: Pendiente
A8: 46152 | B8: COBRO | C8: Cobro exportación (USD 95.000) | D8: 113715000 | E8: 1197 | F8: =IFERROR(D8/E8,0) -> 95000 | G8: Pendiente
A9: 46152 | B9: PAGO | C9: RRHH — sueldos quincena | D9: 96000000 | E9: 1197 | F9: =IFERROR(D9/E9,0) -> 80200.501 | G9: Pendiente
A10: 46154 | B10: PAGO | C10: Arancel / canon mensual | D10: 23000000 | E10: 1197 | F10: =IFERROR(D10/E10,0) -> 19214.703 | G10: Pendiente
A11: 46157 | B11: COBRO | C11: Cheque — Exportadora Patagónica | D11: 145000000 | E11: 1197 | F11: =IFERROR(D11/E11,0) -> 121136.17 | G11: Pendiente
A12: 46162 | B12: PAGO | C12: Deuda proveedor exterior (USD 80.000) | D12: 95760000 | E12: 1197 | F12: =IFERROR(D12/E12,0) -> 80000 | G12: Pendiente

Sheet POSICION_NETA
A1: POSICIÓN FINANCIERA NETA DIARIA | Valores en USD (conversión automática)
A2: ⚠ Hoja de cálculo automática — No modificar. Los datos vienen de CARGA_DIARIA.
A3: Fecha | B3: TC BNA | C3: Activo Corriente (USD) | D3: Gastos del Día (USD) | E3: Pasivo Corriente (USD) | F3: Ajustes + (incluido en Activo) | G3: Ajustes - (incluido en Activo) | H3: POSICIÓN NETA (USD)
A4: =IF(CARGA_DIARIA!A4="","",CARGA_DIARIA!A4) -> 46029 | B4: =IF(CARGA_DIARIA!A4="","",CARGA_DIARIA!B4) -> 1463 | C4: =IF(CARGA_DIARIA!A4="","",IF(CARGA_DIARIA!B4=0,0,(CARGA_DIARIA!C4+CARGA_DIARIA!D4+CARGA_DIARIA!E4+CARGA_DIARIA!F4+CARGA_DIARIA!G4+CARGA_DIARIA!H4+CARGA_DIARIA!I4+CARGA_DIARIA!AG4+CARGA_DIARIA!AH4+CARGA_DIARIA!AI4+CARGA_DIARIA!AJ4)/CARGA_DIARIA!B4+CARGA_DIARIA!AF4)) -> 19059124 | D4: =IF(CARGA_DIARIA!A4="","",IF(CARGA_DIARIA!B4=0,0,(CARGA_DIARIA!J4+CARGA_DIARIA!K4+CARGA_DIARIA!L4+CARGA_DIARIA!M4+CARGA_DIARIA!N4+CARGA_DIARIA!O4+CARGA_DIARIA!P4+CARGA_DIARIA!Q4+CARGA_DIARIA!R4+CARGA_DIARIA!S4+CARGA_DIARIA!T4+CARGA_DIARIA!U4+CARGA_DIARIA!V4+CARGA_DIARIA!W4)/CARGA_DIARIA!B4)) -> 290132.8 | E4: =IF(CARGA_DIARIA!A4="","",IF(CARGA_DIARIA!B4=0,0,(CARGA_DIARIA!X4+CARGA_DIARIA!Y4+CARGA_DIARIA!Z4+CARGA_DIARIA!AA4)/CARGA_DIARIA!B4+CARGA_DIARIA!AB4+CARGA_DIARIA!AC4+CARGA_DIARIA!AD4+CARGA_DIARIA!AE4)) -> 16746778 | F4: — | G4: — | H4: =IF(CARGA_DIARIA!A4="","",C4-D4-E4) -> 2022212.7
A5: =IF(CARGA_DIARIA!A5="","",CARGA_DIARIA!A5) -> 46030 | B5: =IF(CARGA_DIARIA!A5="","",CARGA_DIARIA!B5) -> 1469 | C5: =IF(CARGA_DIARIA!A5="","",IF(CARGA_DIARIA!B5=0,0,(CARGA_DIARIA!C5+CARGA_DIARIA!D5+CARGA_DIARIA!E5+CARGA_DIARIA!F5+CARGA_DIARIA!G5+CARGA_DIARIA!H5+CARGA_DIARIA!I5+CARGA_DIARIA!AG5+CARGA_DIARIA!AH5+CARGA_DIARIA!AI5+CARGA_DIARIA!AJ5)/CARGA_DIARIA!B5+CARGA_DIARIA!AF5)) -> 18101966 | D5: =IF(CARGA_DIARIA!A5="","",IF(CARGA_DIARIA!B5=0,0,(CARGA_DIARIA!J5+CARGA_DIARIA!K5+CARGA_DIARIA!L5+CARGA_DIARIA!M5+CARGA_DIARIA!N5+CARGA_DIARIA!O5+CARGA_DIARIA!P5+CARGA_DIARIA!Q5+CARGA_DIARIA!R5+CARGA_DIARIA!S5+CARGA_DIARIA!T5+CARGA_DIARIA!U5+CARGA_DIARIA!V5+CARGA_DIARIA!W5)/CARGA_DIARIA!B5)) -> 350053.34 | E5: =IF(CARGA_DIARIA!A5="","",IF(CARGA_DIARIA!B5=0,0,(CARGA_DIARIA!X5+CARGA_DIARIA!Y5+CARGA_DIARIA!Z5+CARGA_DIARIA!AA5)/CARGA_DIARIA!B5+CARGA_DIARIA!AB5+CARGA_DIARIA!AC5+CARGA_DIARIA!AD5+CARGA_DIARIA!AE5)) -> 16647892 | F5: — | G5: — | H5: =IF(CARGA_DIARIA!A5="","",C5-D5-E5) -> 1104020.9
A6: =IF(CARGA_DIARIA!A6="","",CARGA_DIARIA!A6) -> 46031 | B6: =IF(CARGA_DIARIA!A6="","",CARGA_DIARIA!B6) -> 1455 | C6: =IF(CARGA_DIARIA!A6="","",IF(CARGA_DIARIA!B6=0,0,(CARGA_DIARIA!C6+CARGA_DIARIA!D6+CARGA_DIARIA!E6+CARGA_DIARIA!F6+CARGA_DIARIA!G6+CARGA_DIARIA!H6+CARGA_DIARIA!I6+CARGA_DIARIA!AG6+CARGA_DIARIA!AH6+CARGA_DIARIA!AI6+CARGA_DIARIA!AJ6)/CARGA_DIARIA!B6+CARGA_DIARIA!AF6)) -> 18851671 | D6: =IF(CARGA_DIARIA!A6="","",IF(CARGA_DIARIA!B6=0,0,(CARGA_DIARIA!J6+CARGA_DIARIA!K6+CARGA_DIARIA!L6+CARGA_DIARIA!M6+CARGA_DIARIA!N6+CARGA_DIARIA!O6+CARGA_DIARIA!P6+CARGA_DIARIA!Q6+CARGA_DIARIA!R6+CARGA_DIARIA!S6+CARGA_DIARIA!T6+CARGA_DIARIA!U6+CARGA_DIARIA!V6+CARGA_DIARIA!W6)/CARGA_DIARIA!B6)) -> 93342.511 | E6: =IF(CARGA_DIARIA!A6="","",IF(CARGA_DIARIA!B6=0,0,(CARGA_DIARIA!X6+CARGA_DIARIA!Y6+CARGA_DIARIA!Z6+CARGA_DIARIA!AA6)/CARGA_DIARIA!B6+CARGA_DIARIA!AB6+CARGA_DIARIA!AC6+CARGA_DIARIA!AD6+CARGA_DIARIA!AE6)) -> 15918601 | F6: — | G6: — | H6: =IF(CARGA_DIARIA!A6="","",C6-D6-E6) -> 2839727
A7: =IF(CARGA_DIARIA!A7="","",CARGA_DIARIA!A7) -> 46034 | B7: =IF(CARGA_DIARIA!A7="","",CARGA_DIARIA!B7) -> 1465.5 | C7: =IF(CARGA_DIARIA!A7="","",IF(CARGA_DIARIA!B7=0,0,(CARGA_DIARIA!C7+CARGA_DIARIA!D7+CARGA_DIARIA!E7+CARGA_DIARIA!F7+CARGA_DIARIA!G7+CARGA_DIARIA!H7+CARGA_DIARIA!I7+CARGA_DIARIA!AG7+CARGA_DIARIA!AH7+CARGA_DIARIA!AI7+CARGA_DIARIA!AJ7)/CARGA_DIARIA!B7+CARGA_DIARIA!AF7)) -> 18930220 | D7: =IF(CARGA_DIARIA!A7="","",IF(CARGA_DIARIA!B7=0,0,(CARGA_DIARIA!J7+CARGA_DIARIA!K7+CARGA_DIARIA!L7+CARGA_DIARIA!M7+CARGA_DIARIA!N7+CARGA_DIARIA!O7+CARGA_DIARIA!P7+CARGA_DIARIA!Q7+CARGA_DIARIA!R7+CARGA_DIARIA!S7+CARGA_DIARIA!T7+CARGA_DIARIA!U7+CARGA_DIARIA!V7+CARGA_DIARIA!W7)/CARGA_DIARIA!B7)) -> 269697.4 | E7: =IF(CARGA_DIARIA!A7="","",IF(CARGA_DIARIA!B7=0,0,(CARGA_DIARIA!X7+CARGA_DIARIA!Y7+CARGA_DIARIA!Z7+CARGA_DIARIA!AA7)/CARGA_DIARIA!B7+CARGA_DIARIA!AB7+CARGA_DIARIA!AC7+CARGA_DIARIA!AD7+CARGA_DIARIA!AE7)) -> 16152946 | F7: — | G7: — | H7: =IF(CARGA_DIARIA!A7="","",C7-D7-E7) -> 2507577.1
A8: =IF(CARGA_DIARIA!A8="","",CARGA_DIARIA!A8) -> 46035 | B8: =IF(CARGA_DIARIA!A8="","",CARGA_DIARIA!B8) -> 1462 | C8: =IF(CARGA_DIARIA!A8="","",IF(CARGA_DIARIA!B8=0,0,(CARGA_DIARIA!C8+CARGA_DIARIA!D8+CARGA_DIARIA!E8+CARGA_DIARIA!F8+CARGA_DIARIA!G8+CARGA_DIARIA!H8+CARGA_DIARIA!I8+CARGA_DIARIA!AG8+CARGA_DIARIA!AH8+CARGA_DIARIA!AI8+CARGA_DIARIA!AJ8)/CARGA_DIARIA!B8+CARGA_DIARIA!AF8)) -> 19304446 | D8: =IF(CARGA_DIARIA!A8="","",IF(CARGA_DIARIA!B8=0,0,(CARGA_DIARIA!J8+CARGA_DIARIA!K8+CARGA_DIARIA!L8+CARGA_DIARIA!M8+CARGA_DIARIA!N8+CARGA_DIARIA!O8+CARGA_DIARIA!P8+CARGA_DIARIA!Q8+CARGA_DIARIA!R8+CARGA_DIARIA!S8+CARGA_DIARIA!T8+CARGA_DIARIA!U8+CARGA_DIARIA!V8+CARGA_DIARIA!W8)/CARGA_DIARIA!B8)) -> 275609.77 | E8: =IF(CARGA_DIARIA!A8="","",IF(CARGA_DIARIA!B8=0,0,(CARGA_DIARIA!X8+CARGA_DIARIA!Y8+CARGA_DIARIA!Z8+CARGA_DIARIA!AA8)/CARGA_DIARIA!B8+CARGA_DIARIA!AB8+CARGA_DIARIA!AC8+CARGA_DIARIA!AD8+CARGA_DIARIA!AE8)) -> 15935429 | F8: — | G8: — | H8: =IF(CARGA_DIARIA!A8="","",C8-D8-E8) -> 3093407.3
A9: =IF(CARGA_DIARIA!A9="","",CARGA_DIARIA!A9) -> 46036 | B9: =IF(CARGA_DIARIA!A9="","",CARGA_DIARIA!B9) -> 1464.5 | C9: =IF(CARGA_DIARIA!A9="","",IF(CARGA_DIARIA!B9=0,0,(CARGA_DIARIA!C9+CARGA_DIARIA!D9+CARGA_DIARIA!E9+CARGA_DIARIA!F9+CARGA_DIARIA!G9+CARGA_DIARIA!H9+CARGA_DIARIA!I9+CARGA_DIARIA!AG9+CARGA_DIARIA!AH9+CARGA_DIARIA!AI9+CARGA_DIARIA!AJ9)/CARGA_DIARIA!B9+CARGA_DIARIA!AF9)) -> 18887090 | D9: =IF(CARGA_DIARIA!A9="","",IF(CARGA_DIARIA!B9=0,0,(CARGA_DIARIA!J9+CARGA_DIARIA!K9+CARGA_DIARIA!L9+CARGA_DIARIA!M9+CARGA_DIARIA!N9+CARGA_DIARIA!O9+CARGA_DIARIA!P9+CARGA_DIARIA!Q9+CARGA_DIARIA!R9+CARGA_DIARIA!S9+CARGA_DIARIA!T9+CARGA_DIARIA!U9+CARGA_DIARIA!V9+CARGA_DIARIA!W9)/CARGA_DIARIA!B9)) -> 241159.25 | E9: =IF(CARGA_DIARIA!A9="","",IF(CARGA_DIARIA!B9=0,0,(CARGA_DIARIA!X9+CARGA_DIARIA!Y9+CARGA_DIARIA!Z9+CARGA_DIARIA!AA9)/CARGA_DIARIA!B9+CARGA_DIARIA!AB9+CARGA_DIARIA!AC9+CARGA_DIARIA!AD9+CARGA_DIARIA!AE9)) -> 15830370 | F9: — | G9: — | H9: =IF(CARGA_DIARIA!A9="","",C9-D9-E9) -> 2815560.9
A10: =IF(CARGA_DIARIA!A10="","",CARGA_DIARIA!A10) -> 46037 | B10: =IF(CARGA_DIARIA!A10="","",CARGA_DIARIA!B10) -> 1450 | C10: =IF(CARGA_DIARIA!A10="","",IF(CARGA_DIARIA!B10=0,0,(CARGA_DIARIA!C10+CARGA_DIARIA!D10+CARGA_DIARIA!E10+CARGA_DIARIA!F10+CARGA_DIARIA!G10+CARGA_DIARIA!H10+CARGA_DIARIA!I10+CARGA_DIARIA!AG10+CARGA_DIARIA!AH10+CARGA_DIARIA!AI10+CARGA_DIARIA!AJ10)/CARGA_DIARIA!B10+CARGA_DIARIA!AF10)) -> 19136047 | D10: =IF(CARGA_DIARIA!A10="","",IF(CARGA_DIARIA!B10=0,0,(CARGA_DIARIA!J10+CARGA_DIARIA!K10+CARGA_DIARIA!L10+CARGA_DIARIA!M10+CARGA_DIARIA!N10+CARGA_DIARIA!O10+CARGA_DIARIA!P10+CARGA_DIARIA!Q10+CARGA_DIARIA!R10+CARGA_DIARIA!S10+CARGA_DIARIA!T10+CARGA_DIARIA!U10+CARGA_DIARIA!V10+CARGA_DIARIA!W10)/CARGA_DIARIA!B10)) -> 332734.66 | E10: =IF(CARGA_DIARIA!A10="","",IF(CARGA_DIARIA!B10=0,0,(CARGA_DIARIA!X10+CARGA_DIARIA!Y10+CARGA_DIARIA!Z10+CARGA_DIARIA!AA10)/CARGA_DIARIA!B10+CARGA_DIARIA!AB10+CARGA_DIARIA!AC10+CARGA_DIARIA!AD10+CARGA_DIARIA!AE10)) -> 15774051 | F10: — | G10: — | H10: =IF(CARGA_DIARIA!A10="","",C10-D10-E10) -> 3029261.8
A11: =IF(CARGA_DIARIA!A11="","",CARGA_DIARIA!A11) -> 46038 | B11: =IF(CARGA_DIARIA!A11="","",CARGA_DIARIA!B11) -> 1440 | C11: =IF(CARGA_DIARIA!A11="","",IF(CARGA_DIARIA!B11=0,0,(CARGA_DIARIA!C11+CARGA_DIARIA!D11+CARGA_DIARIA!E11+CARGA_DIARIA!F11+CARGA_DIARIA!G11+CARGA_DIARIA!H11+CARGA_DIARIA!I11+CARGA_DIARIA!AG11+CARGA_DIARIA!AH11+CARGA_DIARIA!AI11+CARGA_DIARIA!AJ11)/CARGA_DIARIA!B11+CARGA_DIARIA!AF11)) -> 19578702 | D11: =IF(CARGA_DIARIA!A11="","",IF(CARGA_DIARIA!B11=0,0,(CARGA_DIARIA!J11+CARGA_DIARIA!K11+CARGA_DIARIA!L11+CARGA_DIARIA!M11+CARGA_DIARIA!N11+CARGA_DIARIA!O11+CARGA_DIARIA!P11+CARGA_DIARIA!Q11+CARGA_DIARIA!R11+CARGA_DIARIA!S11+CARGA_DIARIA!T11+CARGA_DIARIA!U11+CARGA_DIARIA!V11+CARGA_DIARIA!W11)/CARGA_DIARIA!B11)) -> 134777.6 | E11: =IF(CARGA_DIARIA!A11="","",IF(CARGA_DIARIA!B11=0,0,(CARGA_DIARIA!X11+CARGA_DIARIA!Y11+CARGA_DIARIA!Z11+CARGA_DIARIA!AA11)/CARGA_DIARIA!B11+CARGA_DIARIA!AB11+CARGA_DIARIA!AC11+CARGA_DIARIA!AD11+CARGA_DIARIA!AE11)) -> 15465779 | F11: — | G11: — | H11: =IF(CARGA_DIARIA!A11="","",C11-D11-E11) -> 3978145.2
A12: =IF(CARGA_DIARIA!A12="","",CARGA_DIARIA!A12) -> 46041 | B12: =IF(CARGA_DIARIA!A12="","",CARGA_DIARIA!B12) -> 1428 | C12: =IF(CARGA_DIARIA!A12="","",IF(CARGA_DIARIA!B12=0,0,(CARGA_DIARIA!C12+CARGA_DIARIA!D12+CARGA_DIARIA!E12+CARGA_DIARIA!F12+CARGA_DIARIA!G12+CARGA_DIARIA!H12+CARGA_DIARIA!I12+CARGA_DIARIA!AG12+CARGA_DIARIA!AH12+CARGA_DIARIA!AI12+CARGA_DIARIA!AJ12)/CARGA_DIARIA!B12+CARGA_DIARIA!AF12)) -> 20822019 | D12: =IF(CARGA_DIARIA!A12="","",IF(CARGA_DIARIA!B12=0,0,(CARGA_DIARIA!J12+CARGA_DIARIA!K12+CARGA_DIARIA!L12+CARGA_DIARIA!M12+CARGA_DIARIA!N12+CARGA_DIARIA!O12+CARGA_DIARIA!P12+CARGA_DIARIA!Q12+CARGA_DIARIA!R12+CARGA_DIARIA!S12+CARGA_DIARIA!T12+CARGA_DIARIA!U12+CARGA_DIARIA!V12+CARGA_DIARIA!W12)/CARGA_DIARIA!B12)) -> 163030.93 | E12: =IF(CARGA_DIARIA!A12="","",IF(CARGA_DIARIA!B12=0,0,(CARGA_DIARIA!X12+CARGA_DIARIA!Y12+CARGA_DIARIA!Z12+CARGA_DIARIA!AA12)/CARGA_DIARIA!B12+CARGA_DIARIA!AB12+CARGA_DIARIA!AC12+CARGA_DIARIA!AD12+CARGA_DIARIA!AE12)) -> 14933647 | F12: — | G12: — | H12: =IF(CARGA_DIARIA!A12="","",C12-D12-E12) -> 5725340.2
A13: =IF(CARGA_DIARIA!A13="","",CARGA_DIARIA!A13) -> 46042 | B13: =IF(CARGA_DIARIA!A13="","",CARGA_DIARIA!B13) -> 1428.5 | C13: =IF(CARGA_DIARIA!A13="","",IF(CARGA_DIARIA!B13=0,0,(CARGA_DIARIA!C13+CARGA_DIARIA!D13+CARGA_DIARIA!E13+CARGA_DIARIA!F13+CARGA_DIARIA!G13+CARGA_DIARIA!H13+CARGA_DIARIA!I13+CARGA_DIARIA!AG13+CARGA_DIARIA!AH13+CARGA_DIARIA!AI13+CARGA_DIARIA!AJ13)/CARGA_DIARIA!B13+CARGA_DIARIA!AF13)) -> 21139012 | D13: =IF(CARGA_DIARIA!A13="","",IF(CARGA_DIARIA!B13=0,0,(CARGA_DIARIA!J13+CARGA_DIARIA!K13+CARGA_DIARIA!L13+CARGA_DIARIA!M13+CARGA_DIARIA!N13+CARGA_DIARIA!O13+CARGA_DIARIA!P13+CARGA_DIARIA!Q13+CARGA_DIARIA!R13+CARGA_DIARIA!S13+CARGA_DIARIA!T13+CARGA_DIARIA!U13+CARGA_DIARIA!V13+CARGA_DIARIA!W13)/CARGA_DIARIA!B13)) -> 357428.56 | E13: =IF(CARGA_DIARIA!A13="","",IF(CARGA_DIARIA!B13=0,0,(CARGA_DIARIA!X13+CARGA_DIARIA!Y13+CARGA_DIARIA!Z13+CARGA_DIARIA!AA13)/CARGA_DIARIA!B13+CARGA_DIARIA!AB13+CARGA_DIARIA!AC13+CARGA_DIARIA!AD13+CARGA_DIARIA!AE13)) -> 15449352 | F13: — | G13: — | H13: =IF(CARGA_DIARIA!A13="","",C13-D13-E13) -> 5332231.7
A14: =IF(CARGA_DIARIA!A14="","",CARGA_DIARIA!A14) -> 46043 | B14: =IF(CARGA_DIARIA!A14="","",CARGA_DIARIA!B14) -> 1432 | C14: =IF(CARGA_DIARIA!A14="","",IF(CARGA_DIARIA!B14=0,0,(CARGA_DIARIA!C14+CARGA_DIARIA!D14+CARGA_DIARIA!E14+CARGA_DIARIA!F14+CARGA_DIARIA!G14+CARGA_DIARIA!H14+CARGA_DIARIA!I14+CARGA_DIARIA!AG14+CARGA_DIARIA!AH14+CARGA_DIARIA!AI14+CARGA_DIARIA!AJ14)/CARGA_DIARIA!B14+CARGA_DIARIA!AF14)) -> 21488028 | D14: =IF(CARGA_DIARIA!A14="","",IF(CARGA_DIARIA!B14=0,0,(CARGA_DIARIA!J14+CARGA_DIARIA!K14+CARGA_DIARIA!L14+CARGA_DIARIA!M14+CARGA_DIARIA!N14+CARGA_DIARIA!O14+CARGA_DIARIA!P14+CARGA_DIARIA!Q14+CARGA_DIARIA!R14+CARGA_DIARIA!S14+CARGA_DIARIA!T14+CARGA_DIARIA!U14+CARGA_DIARIA!V14+CARGA_DIARIA!W14)/CARGA_DIARIA!B14)) -> 251536.26 | E14: =IF(CARGA_DIARIA!A14="","",IF(CARGA_DIARIA!B14=0,0,(CARGA_DIARIA!X14+CARGA_DIARIA!Y14+CARGA_DIARIA!Z14+CARGA_DIARIA!AA14)/CARGA_DIARIA!B14+CARGA_DIARIA!AB14+CARGA_DIARIA!AC14+CARGA_DIARIA!AD14+CARGA_DIARIA!AE14)) -> 15559503 | F14: — | G14: — | H14: =IF(CARGA_DIARIA!A14="","",C14-D14-E14) -> 5676988.7
A15: =IF(CARGA_DIARIA!A15="","",CARGA_DIARIA!A15) -> 46044 | B15: =IF(CARGA_DIARIA!A15="","",CARGA_DIARIA!B15) -> 1427 | C15: =IF(CARGA_DIARIA!A15="","",IF(CARGA_DIARIA!B15=0,0,(CARGA_DIARIA!C15+CARGA_DIARIA!D15+CARGA_DIARIA!E15+CARGA_DIARIA!F15+CARGA_DIARIA!G15+CARGA_DIARIA!H15+CARGA_DIARIA!I15+CARGA_DIARIA!AG15+CARGA_DIARIA!AH15+CARGA_DIARIA!AI15+CARGA_DIARIA!AJ15)/CARGA_DIARIA!B15+CARGA_DIARIA!AF15)) -> 21827494 | D15: =IF(CARGA_DIARIA!A15="","",IF(CARGA_DIARIA!B15=0,0,(CARGA_DIARIA!J15+CARGA_DIARIA!K15+CARGA_DIARIA!L15+CARGA_DIARIA!M15+CARGA_DIARIA!N15+CARGA_DIARIA!O15+CARGA_DIARIA!P15+CARGA_DIARIA!Q15+CARGA_DIARIA!R15+CARGA_DIARIA!S15+CARGA_DIARIA!T15+CARGA_DIARIA!U15+CARGA_DIARIA!V15+CARGA_DIARIA!W15)/CARGA_DIARIA!B15)) -> 164046.41 | E15: =IF(CARGA_DIARIA!A15="","",IF(CARGA_DIARIA!B15=0,0,(CARGA_DIARIA!X15+CARGA_DIARIA!Y15+CARGA_DIARIA!Z15+CARGA_DIARIA!AA15)/CARGA_DIARIA!B15+CARGA_DIARIA!AB15+CARGA_DIARIA!AC15+CARGA_DIARIA!AD15+CARGA_DIARIA!AE15)) -> 15422836 | F15: — | G15: — | H15: =IF(CARGA_DIARIA!A15="","",C15-D15-E15) -> 6240611.7
... A117: =IF(CARGA_DIARIA!A117="","",CARGA_DIARIA!A117) -> 46203 | B117: =IF(CARGA_DIARIA!A117="","",CARGA_DIARIA!B117) -> 1472.5 | C117: =IF(CARGA_DIARIA!A117="","",IF(CARGA_DIARIA!B117=0,0,(CARGA_DIARIA!C117+CARGA_DIARIA!D117+CARGA_DIARIA!E117+CARGA_DIARIA!F117+CARGA_DIARIA!G117+CARGA_DIARIA!H117+CARGA_DIARIA!I117+CARGA_DIARIA!AG117+CARGA_DIARIA!AH117+CARGA_DIARIA!AI117+CARGA_DIARIA!AJ117)/CARGA_DIARIA!B117+CARGA_DIARIA!AF117)) -> 30886658 | D117: =IF(CARGA_DIARIA!A117="","",IF(CARGA_DIARIA!B117=0,0,(CARGA_DIARIA!J117+CARGA_DIARIA!K117+CARGA_DIARIA!L117+CARGA_DIARIA!M117+CARGA_DIARIA!N117+CARGA_DIARIA!O117+CARGA_DIARIA!P117+CARGA_DIARIA!Q117+CARGA_DIARIA!R117+CARGA_DIARIA!S117+CARGA_DIARIA!T117+CARGA_DIARIA!U117+CARGA_DIARIA!V117+CARGA_DIARIA!W117)/CARGA_DIARIA!B117)) -> 468105.49 | E117: =IF(CARGA_DIARIA!A117="","",IF(CARGA_DIARIA!B117=0,0,(CARGA_DIARIA!X117+CARGA_DIARIA!Y117+CARGA_DIARIA!Z117+CARGA_DIARIA!AA117)/CARGA_DIARIA!B117+CARGA_DIARIA!AB117+CARGA_DIARIA!AC117+CARGA_DIARIA!AD117+CARGA_DIARIA!AE117)) -> 17984961 | F117: — | G117: — | H117: =IF(CARGA_DIARIA!A117="","",C117-D117-E117) -> 12433592
A118: =IF(CARGA_DIARIA!B118="","",CARGA_DIARIA!B118) -> 1478 | B118: =IF(CARGA_DIARIA!B118="","",CARGA_DIARIA!#REF!) -> #REF! | C118: =IF(CARGA_DIARIA!B118="","",IF(CARGA_DIARIA!#REF!=0,0,(CARGA_DIARIA!C118+CARGA_DIARIA!D118+CARGA_DIARIA!E118+CARGA_DIARIA!F118+CARGA_DIARIA!G118+CARGA_DIARIA!H118+CARGA_DIARIA!I118+CARGA_DIARIA!AG118+CARGA_DIARIA!AH118+CARGA_DIARIA!AI118+CARGA_DIARIA!AJ118)/CARGA_DIARIA!#REF!+CARGA_DIARIA!AF118)) -> #REF! | D118: =IF(CARGA_DIARIA!B118="","",IF(CARGA_DIARIA!#REF!=0,0,(CARGA_DIARIA!J118+CARGA_DIARIA!K118+CARGA_DIARIA!L118+CARGA_DIARIA!M118+CARGA_DIARIA!N118+CARGA_DIARIA!O118+CARGA_DIARIA!P118+CARGA_DIARIA!Q118+CARGA_DIARIA!R118+CARGA_DIARIA!S118+CARGA_DIARIA!T118+CARGA_DIARIA!U118+CARGA_DIARIA!V118+CARGA_DIARIA!W118)/CARGA_DIARIA!#REF!)) -> #REF! | E118: =IF(CARGA_DIARIA!B118="","",IF(CARGA_DIARIA!#REF!=0,0,(CARGA_DIARIA!X118+CARGA_DIARIA!Y118+CARGA_DIARIA!Z118+CARGA_DIARIA!AA118)/CARGA_DIARIA!#REF!+CARGA_DIARIA!AB118+CARGA_DIARIA!AC118+CARGA_DIARIA!AD118+CARGA_DIARIA!AE118)) -> #REF! | F118: — | G118: — | H118: =IF(CARGA_DIARIA!B118="","",C118-D118-E118) -> #REF!
A119: =IF(CARGA_DIARIA!B119="","",CARGA_DIARIA!B119) -> 1485 | B119: =IF(CARGA_DIARIA!B119="","",CARGA_DIARIA!#REF!) -> #REF! | C119: =IF(CARGA_DIARIA!B119="","",IF(CARGA_DIARIA!#REF!=0,0,(CARGA_DIARIA!C119+CARGA_DIARIA!D119+CARGA_DIARIA!E119+CARGA_DIARIA!F119+CARGA_DIARIA!G119+CARGA_DIARIA!H119+CARGA_DIARIA!I119+CARGA_DIARIA!AG119+CARGA_DIARIA!AH119+CARGA_DIARIA!AI119+CARGA_DIARIA!AJ119)/CARGA_DIARIA!#REF!+CARGA_DIARIA!AF119)) -> #REF! | D119: =IF(CARGA_DIARIA!B119="","",IF(CARGA_DIARIA!#REF!=0,0,(CARGA_DIARIA!J119+CARGA_DIARIA!K119+CARGA_DIARIA!L119+CARGA_DIARIA!M119+CARGA_DIARIA!N119+CARGA_DIARIA!O119+CARGA_DIARIA!P119+CARGA_DIARIA!Q119+CARGA_DIARIA!R119+CARGA_DIARIA!S119+CARGA_DIARIA!T119+CARGA_DIARIA!U119+CARGA_DIARIA!V119+CARGA_DIARIA!W119)/CARGA_DIARIA!#REF!)) -> #REF! | E119: =IF(CARGA_DIARIA!B119="","",IF(CARGA_DIARIA!#REF!=0,0,(CARGA_DIARIA!X119+CARGA_DIARIA!Y119+CARGA_DIARIA!Z119+CARGA_DIARIA!AA119)/CARGA_DIARIA!#REF!+CARGA_DIARIA!AB119+CARGA_DIARIA!AC119+CARGA_DIARIA!AD119+CARGA_DIARIA!AE119)) -> #REF! | F119: — | G119: — | H119: =IF(CARGA_DIARIA!B119="","",C119-D119-E119) -> #REF!
A120: =IF(CARGA_DIARIA!B120="","",CARGA_DIARIA!B120) -> 1488 | B120: =IF(CARGA_DIARIA!B120="","",CARGA_DIARIA!#REF!) -> #REF! | C120: =IF(CARGA_DIARIA!B120="","",IF(CARGA_DIARIA!#REF!=0,0,(CARGA_DIARIA!C120+CARGA_DIARIA!D120+CARGA_DIARIA!E120+CARGA_DIARIA!F120+CARGA_DIARIA!G120+CARGA_DIARIA!H120+CARGA_DIARIA!I120+CARGA_DIARIA!AG120+CARGA_DIARIA!AH120+CARGA_DIARIA!AI120+CARGA_DIARIA!AJ120)/CARGA_DIARIA!#REF!+CARGA_DIARIA!AF120)) -> #REF! | D120: =IF(CARGA_DIARIA!B120="","",IF(CARGA_DIARIA!#REF!=0,0,(CARGA_DIARIA!J120+CARGA_DIARIA!K120+CARGA_DIARIA!L120+CARGA_DIARIA!M120+CARGA_DIARIA!N120+CARGA_DIARIA!O120+CARGA_DIARIA!P120+CARGA_DIARIA!Q120+CARGA_DIARIA!R120+CARGA_DIARIA!S120+CARGA_DIARIA!T120+CARGA_DIARIA!U120+CARGA_DIARIA!V120+CARGA_DIARIA!W120)/CARGA_DIARIA!#REF!)) -> #REF! | E120: =IF(CARGA_DIARIA!B120="","",IF(CARGA_DIARIA!#REF!=0,0,(CARGA_DIARIA!X120+CARGA_DIARIA!Y120+CARGA_DIARIA!Z120+CARGA_DIARIA!AA120)/CARGA_DIARIA!#REF!+CARGA_DIARIA!AB120+CARGA_DIARIA!AC120+CARGA_DIARIA!AD120+CARGA_DIARIA!AE120)) -> #REF! | F120: — | G120: — | H120: =IF(CARGA_DIARIA!B120="","",C120-D120-E120) -> #REF!
A121: =IF(CARGA_DIARIA!B121="","",CARGA_DIARIA!B121) -> 1488 | B121: =IF(CARGA_DIARIA!B121="","",CARGA_DIARIA!#REF!) -> #REF! | C121: =IF(CARGA_DIARIA!B121="","",IF(CARGA_DIARIA!#REF!=0,0,(CARGA_DIARIA!C121+CARGA_DIARIA!D121+CARGA_DIARIA!E121+CARGA_DIARIA!F121+CARGA_DIARIA!G121+CARGA_DIARIA!H121+CARGA_DIARIA!I121+CARGA_DIARIA!AG121+CARGA_DIARIA!AH121+CARGA_DIARIA!AI121+CARGA_DIARIA!AJ121)/CARGA_DIARIA!#REF!+CARGA_DIARIA!AF121)) -> #REF! | D121: =IF(CARGA_DIARIA!B121="","",IF(CARGA_DIARIA!#REF!=0,0,(CARGA_DIARIA!J121+CARGA_DIARIA!K121+CARGA_DIARIA!L121+CARGA_DIARIA!M121+CARGA_DIARIA!N121+CARGA_DIARIA!O121+CARGA_DIARIA!P121+CARGA_DIARIA!Q121+CARGA_DIARIA!R121+CARGA_DIARIA!S121+CARGA_DIARIA!T121+CARGA_DIARIA!U121+CARGA_DIARIA!V121+CARGA_DIARIA!W121)/CARGA_DIARIA!#REF!)) -> #REF! | E121: =IF(CARGA_DIARIA!B121="","",IF(CARGA_DIARIA!#REF!=0,0,(CARGA_DIARIA!X121+CARGA_DIARIA!Y121+CARGA_DIARIA!Z121+CARGA_DIARIA!AA121)/CARGA_DIARIA!#REF!+CARGA_DIARIA!AB121+CARGA_DIARIA!AC121+CARGA_DIARIA!AD121+CARGA_DIARIA!AE121)) -> #REF! | F121: — | G121: — | H121: =IF(CARGA_DIARIA!B121="","",C121-D121-E121) -> #REF!
A122: =IF(CARGA_DIARIA!B122="","",CARGA_DIARIA!B122) -> 1487.5 | B122: =IF(CARGA_DIARIA!B122="","",CARGA_DIARIA!#REF!) -> #REF! | C122: =IF(CARGA_DIARIA!B122="","",IF(CARGA_DIARIA!#REF!=0,0,(CARGA_DIARIA!C122+CARGA_DIARIA!D122+CARGA_DIARIA!E122+CARGA_DIARIA!F122+CARGA_DIARIA!G122+CARGA_DIARIA!H122+CARGA_DIARIA!I122+CARGA_DIARIA!AG122+CARGA_DIARIA!AH122+CARGA_DIARIA!AI122+CARGA_DIARIA!AJ122)/CARGA_DIARIA!#REF!+CARGA_DIARIA!AF122)) -> #REF! | D122: =IF(CARGA_DIARIA!B122="","",IF(CARGA_DIARIA!#REF!=0,0,(CARGA_DIARIA!J122+CARGA_DIARIA!K122+CARGA_DIARIA!L122+CARGA_DIARIA!M122+CARGA_DIARIA!N122+CARGA_DIARIA!O122+CARGA_DIARIA!P122+CARGA_DIARIA!Q122+CARGA_DIARIA!R122+CARGA_DIARIA!S122+CARGA_DIARIA!T122+CARGA_DIARIA!U122+CARGA_DIARIA!V122+CARGA_DIARIA!W122)/CARGA_DIARIA!#REF!)) -> #REF! | E122: =IF(CARGA_DIARIA!B122="","",IF(CARGA_DIARIA!#REF!=0,0,(CARGA_DIARIA!X122+CARGA_DIARIA!Y122+CARGA_DIARIA!Z122+CARGA_DIARIA!AA122)/CARGA_DIARIA!#REF!+CARGA_DIARIA!AB122+CARGA_DIARIA!AC122+CARGA_DIARIA!AD122+CARGA_DIARIA!AE122)) -> #REF! | F122: — | G122: — | H122: =IF(CARGA_DIARIA!B122="","",C122-D122-E122) -> #REF!
A123: =IF(CARGA_DIARIA!B123="","",CARGA_DIARIA!B123) -> 1487 | B123: =IF(CARGA_DIARIA!B123="","",CARGA_DIARIA!#REF!) -> #REF! | C123: =IF(CARGA_DIARIA!B123="","",IF(CARGA_DIARIA!#REF!=0,0,(CARGA_DIARIA!C123+CARGA_DIARIA!D123+CARGA_DIARIA!E123+CARGA_DIARIA!F123+CARGA_DIARIA!G123+CARGA_DIARIA!H123+CARGA_DIARIA!I123+CARGA_DIARIA!AG123+CARGA_DIARIA!AH123+CARGA_DIARIA!AI123+CARGA_DIARIA!AJ123)/CARGA_DIARIA!#REF!+CARGA_DIARIA!AF123)) -> #REF! | D123: =IF(CARGA_DIARIA!B123="","",IF(CARGA_DIARIA!#REF!=0,0,(CARGA_DIARIA!J123+CARGA_DIARIA!K123+CARGA_DIARIA!L123+CARGA_DIARIA!M123+CARGA_DIARIA!N123+CARGA_DIARIA!O123+CARGA_DIARIA!P123+CARGA_DIARIA!Q123+CARGA_DIARIA!R123+CARGA_DIARIA!S123+CARGA_DIARIA!T123+CARGA_DIARIA!U123+CARGA_DIARIA!V123+CARGA_DIARIA!W123)/CARGA_DIARIA!#REF!)) -> #REF! | E123: =IF(CARGA_DIARIA!B123="","",IF(CARGA_DIARIA!#REF!=0,0,(CARGA_DIARIA!X123+CARGA_DIARIA!Y123+CARGA_DIARIA!Z123+CARGA_DIARIA!AA123)/CARGA_DIARIA!#REF!+CARGA_DIARIA!AB123+CARGA_DIARIA!AC123+CARGA_DIARIA!AD123+CARGA_DIARIA!AE123)) -> #REF! | F123: — | G123: — | H123: =IF(CARGA_DIARIA!B123="","",C123-D123-E123) -> #REF!
A124: =IF(CARGA_DIARIA!B124="","",CARGA_DIARIA!B124) -> 1482.5 | B124: =IF(CARGA_DIARIA!B124="","",CARGA_DIARIA!#REF!) -> #REF! | C124: =IF(CARGA_DIARIA!B124="","",IF(CARGA_DIARIA!#REF!=0,0,(CARGA_DIARIA!C124+CARGA_DIARIA!D124+CARGA_DIARIA!E124+CARGA_DIARIA!F124+CARGA_DIARIA!G124+CARGA_DIARIA!H124+CARGA_DIARIA!I124+CARGA_DIARIA!AG124+CARGA_DIARIA!AH124+CARGA_DIARIA!AI124+CARGA_DIARIA!AJ124)/CARGA_DIARIA!#REF!+CARGA_DIARIA!AF124)) -> #REF! | D124: =IF(CARGA_DIARIA!B124="","",IF(CARGA_DIARIA!#REF!=0,0,(CARGA_DIARIA!J124+CARGA_DIARIA!K124+CARGA_DIARIA!L124+CARGA_DIARIA!M124+CARGA_DIARIA!N124+CARGA_DIARIA!O124+CARGA_DIARIA!P124+CARGA_DIARIA!Q124+CARGA_DIARIA!R124+CARGA_DIARIA!S124+CARGA_DIARIA!T124+CARGA_DIARIA!U124+CARGA_DIARIA!V124+CARGA_DIARIA!W124)/CARGA_DIARIA!#REF!)) -> #REF! | E124: =IF(CARGA_DIARIA!B124="","",IF(CARGA_DIARIA!#REF!=0,0,(CARGA_DIARIA!X124+CARGA_DIARIA!Y124+CARGA_DIARIA!Z124+CARGA_DIARIA!AA124)/CARGA_DIARIA!#REF!+CARGA_DIARIA!AB124+CARGA_DIARIA!AC124+CARGA_DIARIA!AD124+CARGA_DIARIA!AE124)) -> #REF! | F124: — | G124: — | H124: =IF(CARGA_DIARIA!B124="","",C124-D124-E124) -> #REF!
A125: =IF(CARGA_DIARIA!A125="","",CARGA_DIARIA!A125) -> 46218 | B125: =IF(CARGA_DIARIA!A125="","",CARGA_DIARIA!B125) -> 1473 | C125: =IF(CARGA_DIARIA!A125="","",IF(CARGA_DIARIA!B125=0,0,(CARGA_DIARIA!C125+CARGA_DIARIA!D125+CARGA_DIARIA!E125+CARGA_DIARIA!F125+CARGA_DIARIA!G125+CARGA_DIARIA!H125+CARGA_DIARIA!I125+CARGA_DIARIA!AG125+CARGA_DIARIA!AH125+CARGA_DIARIA!AI125+CARGA_DIARIA!AJ125)/CARGA_DIARIA!B125+CARGA_DIARIA!AF125)) -> 35175810 | D125: =IF(CARGA_DIARIA!A125="","",IF(CARGA_DIARIA!B125=0,0,(CARGA_DIARIA!J125+CARGA_DIARIA!K125+CARGA_DIARIA!L125+CARGA_DIARIA!M125+CARGA_DIARIA!N125+CARGA_DIARIA!O125+CARGA_DIARIA!P125+CARGA_DIARIA!Q125+CARGA_DIARIA!R125+CARGA_DIARIA!S125+CARGA_DIARIA!T125+CARGA_DIARIA!U125+CARGA_DIARIA!V125+CARGA_DIARIA!W125)/CARGA_DIARIA!B125)) -> 787762.66 | E125: =IF(CARGA_DIARIA!A125="","",IF(CARGA_DIARIA!B125=0,0,(CARGA_DIARIA!X125+CARGA_DIARIA!Y125+CARGA_DIARIA!Z125+CARGA_DIARIA!AA125)/CARGA_DIARIA!B125+CARGA_DIARIA!AB125+CARGA_DIARIA!AC125+CARGA_DIARIA!AD125+CARGA_DIARIA!AE125)) -> 25430698 | F125: — | G125: — | H125: =IF(CARGA_DIARIA!A125="","",C125-D125-E125) -> 8957349.1
A126: =IF(CARGA_DIARIA!A126="","",CARGA_DIARIA!A126) -> 46219 | B126: =IF(CARGA_DIARIA!A126="","",CARGA_DIARIA!B126) -> 1466 | C126: =IF(CARGA_DIARIA!A126="","",IF(CARGA_DIARIA!B126=0,0,(CARGA_DIARIA!C126+CARGA_DIARIA!D126+CARGA_DIARIA!E126+CARGA_DIARIA!F126+CARGA_DIARIA!G126+CARGA_DIARIA!H126+CARGA_DIARIA!I126+CARGA_DIARIA!AG126+CARGA_DIARIA!AH126+CARGA_DIARIA!AI126+CARGA_DIARIA!AJ126)/CARGA_DIARIA!B126+CARGA_DIARIA!AF126)) -> 49177894 | D126: =IF(CARGA_DIARIA!A126="","",IF(CARGA_DIARIA!B126=0,0,(CARGA_DIARIA!J126+CARGA_DIARIA!K126+CARGA_DIARIA!L126+CARGA_DIARIA!M126+CARGA_DIARIA!N126+CARGA_DIARIA!O126+CARGA_DIARIA!P126+CARGA_DIARIA!Q126+CARGA_DIARIA!R126+CARGA_DIARIA!S126+CARGA_DIARIA!T126+CARGA_DIARIA!U126+CARGA_DIARIA!V126+CARGA_DIARIA!W126)/CARGA_DIARIA!B126)) -> 511705.62 | E126: =IF(CARGA_DIARIA!A126="","",IF(CARGA_DIARIA!B126=0,0,(CARGA_DIARIA!X126+CARGA_DIARIA!Y126+CARGA_DIARIA!Z126+CARGA_DIARIA!AA126)/CARGA_DIARIA!B126+CARGA_DIARIA!AB126+CARGA_DIARIA!AC126+CARGA_DIARIA!AD126+CARGA_DIARIA!AE126)) -> 25637323 | F126: — | G126: — | H126: =IF(CARGA_DIARIA!A126="","",C126-D126-E126) -> 23028865
A127: =IF(CARGA_DIARIA!A127="","",CARGA_DIARIA!A127) -> 46220 | B127: =IF(CARGA_DIARIA!A127="","",CARGA_DIARIA!B127) -> 1471 | C127: =IF(CARGA_DIARIA!A127="","",IF(CARGA_DIARIA!B127=0,0,(CARGA_DIARIA!C127+CARGA_DIARIA!D127+CARGA_DIARIA!E127+CARGA_DIARIA!F127+CARGA_DIARIA!G127+CARGA_DIARIA!H127+CARGA_DIARIA!I127+CARGA_DIARIA!AG127+CARGA_DIARIA!AH127+CARGA_DIARIA!AI127+CARGA_DIARIA!AJ127)/CARGA_DIARIA!B127+CARGA_DIARIA!AF127)) -> 50241448 | D127: =IF(CARGA_DIARIA!A127="","",IF(CARGA_DIARIA!B127=0,0,(CARGA_DIARIA!J127+CARGA_DIARIA!K127+CARGA_DIARIA!L127+CARGA_DIARIA!M127+CARGA_DIARIA!N127+CARGA_DIARIA!O127+CARGA_DIARIA!P127+CARGA_DIARIA!Q127+CARGA_DIARIA!R127+CARGA_DIARIA!S127+CARGA_DIARIA!T127+CARGA_DIARIA!U127+CARGA_DIARIA!V127+CARGA_DIARIA!W127)/CARGA_DIARIA!B127)) -> 542846.44 | E127: =IF(CARGA_DIARIA!A127="","",IF(CARGA_DIARIA!B127=0,0,(CARGA_DIARIA!X127+CARGA_DIARIA!Y127+CARGA_DIARIA!Z127+CARGA_DIARIA!AA127)/CARGA_DIARIA!B127+CARGA_DIARIA!AB127+CARGA_DIARIA!AC127+CARGA_DIARIA!AD127+CARGA_DIARIA!AE127)) -> 25964777 | F127: — | G127: — | H127: =IF(CARGA_DIARIA!A127="","",C127-D127-E127) -> 23733825
A128: =IF(CARGA_DIARIA!A128="","",CARGA_DIARIA!A128) -> 46223 | B128: =IF(CARGA_DIARIA!A128="","",CARGA_DIARIA!B128) -> 1476 | C128: =IF(CARGA_DIARIA!A128="","",IF(CARGA_DIARIA!B128=0,0,(CARGA_DIARIA!C128+CARGA_DIARIA!D128+CARGA_DIARIA!E128+CARGA_DIARIA!F128+CARGA_DIARIA!G128+CARGA_DIARIA!H128+CARGA_DIARIA!I128+CARGA_DIARIA!AG128+CARGA_DIARIA!AH128+CARGA_DIARIA!AI128+CARGA_DIARIA!AJ128)/CARGA_DIARIA!B128+CARGA_DIARIA!AF128)) -> 49188149 | D128: =IF(CARGA_DIARIA!A128="","",IF(CARGA_DIARIA!B128=0,0,(CARGA_DIARIA!J128+CARGA_DIARIA!K128+CARGA_DIARIA!L128+CARGA_DIARIA!M128+CARGA_DIARIA!N128+CARGA_DIARIA!O128+CARGA_DIARIA!P128+CARGA_DIARIA!Q128+CARGA_DIARIA!R128+CARGA_DIARIA!S128+CARGA_DIARIA!T128+CARGA_DIARIA!U128+CARGA_DIARIA!V128+CARGA_DIARIA!W128)/CARGA_DIARIA!B128)) -> 640506.91 | E128: =IF(CARGA_DIARIA!A128="","",IF(CARGA_DIARIA!B128=0,0,(CARGA_DIARIA!X128+CARGA_DIARIA!Y128+CARGA_DIARIA!Z128+CARGA_DIARIA!AA128)/CARGA_DIARIA!B128+CARGA_DIARIA!AB128+CARGA_DIARIA!AC128+CARGA_DIARIA!AD128+CARGA_DIARIA!AE128)) -> 24515468 | F128: — | G128: — | H128: =IF(CARGA_DIARIA!A128="","",C128-D128-E128) -> 24032174
